Workbook
Name WEEKS: Inputs!$B$7
Name FIXED_COSTS: Inputs!$B$8
Name TOTAL_BEDS: Inputs!$B$9
Name FARMER_SALARY: Inputs!$B$10
Name FARMER_FIELD_HRS: Inputs!$B$11
Name FARMER_FULL_HRS: Inputs!$B$12
Name TEMP_MAX: Inputs!$B$13
Name TEMP_COST: Inputs!$B$14
Name TEMP_HRS: Inputs!$B$15
Name FARMER_RATE: Inputs!$B$16
Name TEMP_RATE: Inputs!$B$17
Name MAXBED_TOM: Inputs!$B$21
Name MAXBED_CAR: Inputs!$C$21
Name MAXBED_MES: Inputs!$D$21
Name PRICE_TOM: Inputs!$B$22
Name PRICE_CAR: Inputs!$C$22
Name PRICE_MES: Inputs!$D$22
Name HRS_WK_BED_TOM: Inputs!$B$23
Name HRS_WK_BED_CAR: Inputs!$C$23
Name HRS_WK_BED_MES: Inputs!$D$23
Name FERT_TOM: Inputs!$B$24
Name FERT_CAR: Inputs!$C$24
Name FERT_MES: Inputs!$D$24
Name DIM_TOM: Inputs!$B$25
Name DIM_CAR: Inputs!$C$25
Name DIM_MES: Inputs!$D$25
Name SEASON_HRS_TOM: Labor!$C$5
Name STOP_TOM: Labor!$C$27
Name STOPHRS_TOM: Labor!$C$28
Name SEASON_HRS_CAR: Labor!$C$31
Name STOP_CAR: Labor!$C$53
Name STOPHRS_CAR: Labor!$C$54
Name SEASON_HRS_MES: Labor!$C$57
Name STOP_MES: Labor!$C$89
Name STOPHRS_MES: Labor!$C$90
Name OPT_NTEMP_RNG: Optimize!$B$5:$F$5
Name OPT_QTOM_RNG: Optimize!$B$6:$F$6
Name OPT_QCAR_RNG: Optimize!$B$7:$F$7
Name OPT_QMES_RNG: Optimize!$B$8:$F$8
Name OPT_PROFIT_RNG: Optimize!$B$21:$F$21
Name OPT_BEDSUSED_RNG: Optimize!$B$10:$F$10
Name OPT_LABORSLACK_RNG: Optimize!$B$15:$F$15
Name WINIDX: Optimize!$B$25
Name REC_NTEMP: Optimize!$G$5
Name REC_QTOM: Optimize!$G$6
Name REC_QCAR: Optimize!$G$7
Name REC_QMES: Optimize!$G$8
Name REC_PROFIT: Optimize!$G$21
Name REC_BEDSUSED: Optimize!$G$10
Name REC_LABORSLACK: Optimize!$G$15
Name PNL_PROFIT: 'P&L'!$B$30

Sheet Inputs
A1: Marginal Analysis — Perfect Competition (Garden)
A2: Inputs — the named contract
A3: Blue = hardcoded input. Black = computed rate, entered as a formula, never as a rounded literal.
A5: Scenario-wide
A6: Name | B6: Value | C6: Unit | D6: Source
A7: WEEKS | B7: 36 | C7: weeks per season | D7: Case scenario, header line
A8: FIXED_COSTS | B8: 20000 | C8: USD per season | D8: Case scenario, header line
A9: TOTAL_BEDS | B9: 64 | C9: beds (16 beds x 4 plots) | D9: Case scenario, header line
A10: FARMER_SALARY | B10: 50000 | C10: USD per season | D10: Case scenario, header line
A11: FARMER_FIELD_HRS | B11: 720 | C11: hours per season | D11: Case scenario, header line. Her actual field-time contribution to LABOR_SUPPLY — half her working time.
A12: FARMER_FULL_HRS | B12: 1440 | C12: hours per season | D12: Case scenario, header line (implied). A separate, full-time-equivalent hour basis — the same 1440 hours used for a temp's season — that the case's own displayed $34.72/hr figure is built on (50,000/1,440), not her 720 actual field hours (50,000/720 = $69.44/hr). Used only to compute FARMER_RATE below; LABOR_SUPPLY correctly uses FARMER_FIELD_HRS, not this.
A13: TEMP_MAX | B13: 4 | C13: workers | D13: Case scenario, header line
A14: TEMP_COST | B14: 25000 | C14: USD per worker per season | D14: Case scenario, header line
A15: TEMP_HRS | B15: 1440 | C15: hours per worker per season | D15: Case scenario, header line
A16: FARMER_RATE | B16: =Inputs!$B$10/Inputs!$B$12 | C16: USD per hour | D16: Computed: FARMER_SALARY / FARMER_FULL_HRS = 50000/1440. Never entered as the rounded $34.72 the case displays, and never divided by FARMER_FIELD_HRS (720) — that would give $69.44, not the case's figure.
A17: TEMP_RATE | B17: =Inputs!$B$14/Inputs!$B$15 | C17: USD per hour | D17: Computed: TEMP_COST / TEMP_HRS. Never entered as the rounded $17.36 the case displays.
A19: Per crop
A20: Metric | B20: Tomatoes | C20: Carrots | D20: Mesclun | E20: Unit | F20: Source
A21: MAXBED | B21: 20 | C21: 20 | D21: 30 | E21: beds | F21: Case scenario, crop table
A22: PRICE | B22: 8800 | C22: 2094 | D22: 2700 | E22: USD per bed | F22: Case scenario, crop table
A23: HRS_WK_BED | B23: 2.5 | C23: =5/6 | D23: 1.25 | E23: hours per week per bed | F23: Case scenario, crop table. Carrots entered as 5/6, the ratio the case's displayed 0.833 rounds.
A24: FERT | B24: 880 | C24: 440 | D24: 880 | E24: USD per bed | F24: Case scenario, crop table
A25: DIM | B25: 0.1 | C25: 0.025 | D25: 0.0125 | E25: per additional bed | F25: Case scenario, crop table
A28: PRICE_c is revenue per bed — the case has already collapsed price per unit and yield per bed into one figure, so yield is not modeled separately and per-bed revenue does not decline with scale. Every nonlinearity in this model lives in labor hours (see the Labor sheet). Diminishing returns compound on the whole crop, not incrementally per bed: every one of the q beds planted of a crop is charged the same (1+DIM)^q multiplier — see Labor sheet.

Sheet Labor
A1: Labor — marginal hours, marginal cost, and marginal contribution by bed
A2: LABOR_HRS_c(q) = SEASON_HRS_PER_BED_c x q x (1+DIM_c)^q | MARGINAL_LABOR_HRS_c(q) = SEASON_HRS_PER_BED_c x (1+DIM_c)^(q-1) x (1+q x DIM_c) | MC_c(q) = MARGINAL_LABOR_HRS_c(q) x TEMP_RATE + FERT_c
A4: Tomatoes
A5: Season hours/bed (pre-diminishing) = | C5: =HRS_WK_BED_TOM*WEEKS
A6: Bed (q) | B6: Marginal Hours | C6: Cumulative Hours | D6: Marginal Cost ($) | E6: Marginal Contribution ($)
A7: 1 | B7: =SEASON_HRS_TOM*(1+DIM_TOM)^(A7-1)*(1+A7*DIM_TOM) | C7: =SEASON_HRS_TOM*A7*(1+DIM_TOM)^A7 | D7: =B7*TEMP_RATE+FERT_TOM | E7: =PRICE_TOM-D7
A8: 2 | B8: =SEASON_HRS_TOM*(1+DIM_TOM)^(A8-1)*(1+A8*DIM_TOM) | C8: =SEASON_HRS_TOM*A8*(1+DIM_TOM)^A8 | D8: =B8*TEMP_RATE+FERT_TOM | E8: =PRICE_TOM-D8
A9: 3 | B9: =SEASON_HRS_TOM*(1+DIM_TOM)^(A9-1)*(1+A9*DIM_TOM) | C9: =SEASON_HRS_TOM*A9*(1+DIM_TOM)^A9 | D9: =B9*TEMP_RATE+FERT_TOM | E9: =PRICE_TOM-D9
A10: 4 | B10: =SEASON_HRS_TOM*(1+DIM_TOM)^(A10-1)*(1+A10*DIM_TOM) | C10: =SEASON_HRS_TOM*A10*(1+DIM_TOM)^A10 | D10: =B10*TEMP_RATE+FERT_TOM | E10: =PRICE_TOM-D10
A11: 5 | B11: =SEASON_HRS_TOM*(1+DIM_TOM)^(A11-1)*(1+A11*DIM_TOM) | C11: =SEASON_HRS_TOM*A11*(1+DIM_TOM)^A11 | D11: =B11*TEMP_RATE+FERT_TOM | E11: =PRICE_TOM-D11
A12: 6 | B12: =SEASON_HRS_TOM*(1+DIM_TOM)^(A12-1)*(1+A12*DIM_TOM) | C12: =SEASON_HRS_TOM*A12*(1+DIM_TOM)^A12 | D12: =B12*TEMP_RATE+FERT_TOM | E12: =PRICE_TOM-D12
A13: 7 | B13: =SEASON_HRS_TOM*(1+DIM_TOM)^(A13-1)*(1+A13*DIM_TOM) | C13: =SEASON_HRS_TOM*A13*(1+DIM_TOM)^A13 | D13: =B13*TEMP_RATE+FERT_TOM | E13: =PRICE_TOM-D13
A14: 8 | B14: =SEASON_HRS_TOM*(1+DIM_TOM)^(A14-1)*(1+A14*DIM_TOM) | C14: =SEASON_HRS_TOM*A14*(1+DIM_TOM)^A14 | D14: =B14*TEMP_RATE+FERT_TOM | E14: =PRICE_TOM-D14
A15: 9 | B15: =SEASON_HRS_TOM*(1+DIM_TOM)^(A15-1)*(1+A15*DIM_TOM) | C15: =SEASON_HRS_TOM*A15*(1+DIM_TOM)^A15 | D15: =B15*TEMP_RATE+FERT_TOM | E15: =PRICE_TOM-D15
A16: 10 | B16: =SEASON_HRS_TOM*(1+DIM_TOM)^(A16-1)*(1+A16*DIM_TOM) | C16: =SEASON_HRS_TOM*A16*(1+DIM_TOM)^A16 | D16: =B16*TEMP_RATE+FERT_TOM | E16: =PRICE_TOM-D16
A17: 11 | B17: =SEASON_HRS_TOM*(1+DIM_TOM)^(A17-1)*(1+A17*DIM_TOM) | C17: =SEASON_HRS_TOM*A17*(1+DIM_TOM)^A17 | D17: =B17*TEMP_RATE+FERT_TOM | E17: =PRICE_TOM-D17
A18: 12 | B18: =SEASON_HRS_TOM*(1+DIM_TOM)^(A18-1)*(1+A18*DIM_TOM) | C18: =SEASON_HRS_TOM*A18*(1+DIM_TOM)^A18 | D18: =B18*TEMP_RATE+FERT_TOM | E18: =PRICE_TOM-D18
... A26: 20 | B26: =SEASON_HRS_TOM*(1+DIM_TOM)^(A26-1)*(1+A26*DIM_TOM) | C26: =SEASON_HRS_TOM*A26*(1+DIM_TOM)^A26 | D26: =B26*TEMP_RATE+FERT_TOM | E26: =PRICE_TOM-D26
A27: Unconstrained stop (own MC ≤ PRICE): | C27: =COUNTIF(D7:D26,"<="&PRICE_TOM)
A28: Hours needed at that count: | C28: =IF(STOP_TOM=0,0,INDEX(C7:C26,STOP_TOM))
A30: Carrots
A31: Season hours/bed (pre-diminishing) = | C31: =HRS_WK_BED_CAR*WEEKS
A32: Bed (q) | B32: Marginal Hours | C32: Cumulative Hours | D32: Marginal Cost ($) | E32: Marginal Contribution ($)
A33: 1 | B33: =SEASON_HRS_CAR*(1+DIM_CAR)^(A33-1)*(1+A33*DIM_CAR) | C33: =SEASON_HRS_CAR*A33*(1+DIM_CAR)^A33 | D33: =B33*TEMP_RATE+FERT_CAR | E33: =PRICE_CAR-D33
A34: 2 | B34: =SEASON_HRS_CAR*(1+DIM_CAR)^(A34-1)*(1+A34*DIM_CAR) | C34: =SEASON_HRS_CAR*A34*(1+DIM_CAR)^A34 | D34: =B34*TEMP_RATE+FERT_CAR | E34: =PRICE_CAR-D34
A35: 3 | B35: =SEASON_HRS_CAR*(1+DIM_CAR)^(A35-1)*(1+A35*DIM_CAR) | C35: =SEASON_HRS_CAR*A35*(1+DIM_CAR)^A35 | D35: =B35*TEMP_RATE+FERT_CAR | E35: =PRICE_CAR-D35
A36: 4 | B36: =SEASON_HRS_CAR*(1+DIM_CAR)^(A36-1)*(1+A36*DIM_CAR) | C36: =SEASON_HRS_CAR*A36*(1+DIM_CAR)^A36 | D36: =B36*TEMP_RATE+FERT_CAR | E36: =PRICE_CAR-D36
A37: 5 | B37: =SEASON_HRS_CAR*(1+DIM_CAR)^(A37-1)*(1+A37*DIM_CAR) | C37: =SEASON_HRS_CAR*A37*(1+DIM_CAR)^A37 | D37: =B37*TEMP_RATE+FERT_CAR | E37: =PRICE_CAR-D37
A38: 6 | B38: =SEASON_HRS_CAR*(1+DIM_CAR)^(A38-1)*(1+A38*DIM_CAR) | C38: =SEASON_HRS_CAR*A38*(1+DIM_CAR)^A38 | D38: =B38*TEMP_RATE+FERT_CAR | E38: =PRICE_CAR-D38
A39: 7 | B39: =SEASON_HRS_CAR*(1+DIM_CAR)^(A39-1)*(1+A39*DIM_CAR) | C39: =SEASON_HRS_CAR*A39*(1+DIM_CAR)^A39 | D39: =B39*TEMP_RATE+FERT_CAR | E39: =PRICE_CAR-D39
A40: 8 | B40: =SEASON_HRS_CAR*(1+DIM_CAR)^(A40-1)*(1+A40*DIM_CAR) | C40: =SEASON_HRS_CAR*A40*(1+DIM_CAR)^A40 | D40: =B40*TEMP_RATE+FERT_CAR | E40: =PRICE_CAR-D40
A41: 9 | B41: =SEASON_HRS_CAR*(1+DIM_CAR)^(A41-1)*(1+A41*DIM_CAR) | C41: =SEASON_HRS_CAR*A41*(1+DIM_CAR)^A41 | D41: =B41*TEMP_RATE+FERT_CAR | E41: =PRICE_CAR-D41
A42: 10 | B42: =SEASON_HRS_CAR*(1+DIM_CAR)^(A42-1)*(1+A42*DIM_CAR) | C42: =SEASON_HRS_CAR*A42*(1+DIM_CAR)^A42 | D42: =B42*TEMP_RATE+FERT_CAR | E42: =PRICE_CAR-D42
A43: 11 | B43: =SEASON_HRS_CAR*(1+DIM_CAR)^(A43-1)*(1+A43*DIM_CAR) | C43: =SEASON_HRS_CAR*A43*(1+DIM_CAR)^A43 | D43: =B43*TEMP_RATE+FERT_CAR | E43: =PRICE_CAR-D43
A44: 12 | B44: =SEASON_HRS_CAR*(1+DIM_CAR)^(A44-1)*(1+A44*DIM_CAR) | C44: =SEASON_HRS_CAR*A44*(1+DIM_CAR)^A44 | D44: =B44*TEMP_RATE+FERT_CAR | E44: =PRICE_CAR-D44
... A52: 20 | B52: =SEASON_HRS_CAR*(1+DIM_CAR)^(A52-1)*(1+A52*DIM_CAR) | C52: =SEASON_HRS_CAR*A52*(1+DIM_CAR)^A52 | D52: =B52*TEMP_RATE+FERT_CAR | E52: =PRICE_CAR-D52
A53: Unconstrained stop (own MC ≤ PRICE): | C53: =COUNTIF(D33:D52,"<="&PRICE_CAR)
A54: Hours needed at that count: | C54: =IF(STOP_CAR=0,0,INDEX(C33:C52,STOP_CAR))
A56: Mesclun
A57: Season hours/bed (pre-diminishing) = | C57: =HRS_WK_BED_MES*WEEKS
...

Sheet Optimize
A1: Optimize — hiring sweep and bed mix
A2: Each of the 5 columns below is a separate integer optimization: for that N_TEMP, which Q_TOM/Q_CAR/Q_MES maximizes PROFIT subject to BEDS_USED<=TOTAL_BEDS, Q_c<=MAXBED_c, and LABOR_HRS_USED<=LABOR_SUPPLY. Solved by exhaustive integer search (21x21x31 combinations per column, 68,355 total) — reproducible in Excel via Data > Solver on any column: Objective = that column's PROFIT cell (max), By Changing = that column's Q_TOM/Q_CAR/Q_MES cells, Constraints = that column's BEDS_USED<=TOTAL_BEDS, Q_TOM<=MAXBED_TOM, Q_CAR<=MAXBED_CAR, Q_MES<=MAXBED_MES, LABOR_HRS_USED<=LABOR_SUPPLY, all changing cells integer >= 0. GRG Nonlinear will not reliably solve this (the labor formula is non-convex in q); Evolutionary is the setting to use.
A4: Scenario | B4: N_TEMP = 0 | C4: N_TEMP = 1 | D4: N_TEMP = 2 | E4: N_TEMP = 3 | F4: N_TEMP = 4 | G4: Recommended
A5: N_TEMP | B5: 0 | C5: 1 | D5: 2 | E5: 3 | F5: 4 | G5: =INDEX(OPT_NTEMP_RNG,WINIDX)
A6: Q_TOM (beds) | B6: 4 | C6: 6 | D6: 7 | E6: 10 | F6: 12 | G6: =INDEX(OPT_QTOM_RNG,WINIDX)
A7: Q_CAR (beds) | B7: 3 | C7: 10 | D7: 19 | E7: 19 | F7: 20 | G7: =INDEX(OPT_QCAR_RNG,WINIDX)
A8: Q_MES (beds) | B8: 2 | C8: 15 | D8: 24 | E8: 28 | F8: 30 | G8: =INDEX(OPT_QMES_RNG,WINIDX)
A10: BEDS_USED | B10: =B6+B7+B8 | C10: =C6+C7+C8 | D10: =D6+D7+D8 | E10: =E6+E7+E8 | F10: =F6+F7+F8 | G10: =INDEX(OPT_BEDSUSED_RNG,WINIDX)
A11: BEDS_FALLOW | B11: =TOTAL_BEDS-B10 | C11: =TOTAL_BEDS-C10 | D11: =TOTAL_BEDS-D10 | E11: =TOTAL_BEDS-E10 | F11: =TOTAL_BEDS-F10
A13: LABOR_HRS_USED | B13: =SEASON_HRS_TOM*B6*(1+DIM_TOM)^B6+SEASON_HRS_CAR*B7*(1+DIM_CAR)^B7+SEASON_HRS_MES*B8*(1+DIM_MES)^B8 | C13: =SEASON_HRS_TOM*C6*(1+DIM_TOM)^C6+SEASON_HRS_CAR*C7*(1+DIM_CAR)^C7+SEASON_HRS_MES*C8*(1+DIM_MES)^C8 | D13: =SEASON_HRS_TOM*D6*(1+DIM_TOM)^D6+SEASON_HRS_CAR*D7*(1+DIM_CAR)^D7+SEASON_HRS_MES*D8*(1+DIM_MES)^D8 | E13: =SEASON_HRS_TOM*E6*(1+DIM_TOM)^E6+SEASON_HRS_CAR*E7*(1+DIM_CAR)^E7+SEASON_HRS_MES*E8*(1+DIM_MES)^E8 | F13: =SEASON_HRS_TOM*F6*(1+DIM_TOM)^F6+SEASON_HRS_CAR*F7*(1+DIM_CAR)^F7+SEASON_HRS_MES*F8*(1+DIM_MES)^F8
A14: LABOR_SUPPLY | B14: =FARMER_FIELD_HRS+B5*TEMP_HRS | C14: =FARMER_FIELD_HRS+C5*TEMP_HRS | D14: =FARMER_FIELD_HRS+D5*TEMP_HRS | E14: =FARMER_FIELD_HRS+E5*TEMP_HRS | F14: =FARMER_FIELD_HRS+F5*TEMP_HRS
A15: LABOR_SLACK | B15: =B14-B13 | C15: =C14-C13 | D15: =D14-D13 | E15: =E14-E13 | F15: =F14-F13 | G15: =INDEX(OPT_LABORSLACK_RNG,WINIDX)
A17: REVENUE | B17: =B6*PRICE_TOM+B7*PRICE_CAR+B8*PRICE_MES | C17: =C6*PRICE_TOM+C7*PRICE_CAR+C8*PRICE_MES | D17: =D6*PRICE_TOM+D7*PRICE_CAR+D8*PRICE_MES | E17: =E6*PRICE_TOM+E7*PRICE_CAR+E8*PRICE_MES | F17: =F6*PRICE_TOM+F7*PRICE_CAR+F8*PRICE_MES
A18: FERT_COST | B18: =B6*FERT_TOM+B7*FERT_CAR+B8*FERT_MES | C18: =C6*FERT_TOM+C7*FERT_CAR+C8*FERT_MES | D18: =D6*FERT_TOM+D7*FERT_CAR+D8*FERT_MES | E18: =E6*FERT_TOM+E7*FERT_CAR+E8*FERT_MES | F18: =F6*FERT_TOM+F7*FERT_CAR+F8*FERT_MES
A19: LABOR_CASH_COST | B19: =FARMER_SALARY+B5*TEMP_COST | C19: =FARMER_SALARY+C5*TEMP_COST | D19: =FARMER_SALARY+D5*TEMP_COST | E19: =FARMER_SALARY+E5*TEMP_COST | F19: =FARMER_SALARY+F5*TEMP_COST
A20: FIXED_COSTS | B20: =FIXED_COSTS | C20: =FIXED_COSTS | D20: =FIXED_COSTS | E20: =FIXED_COSTS | F20: =FIXED_COSTS
A21: PROFIT | B21: =B17-B18-B19-B20 | C21: =C17-C18-C19-C20 | D21: =D17-D18-D19-D20 | E21: =E17-E18-E19-E20 | F21: =F17-F18-F19-F20 | G21: =INDEX(OPT_PROFIT_RNG,WINIDX)
A23: Profit-maximizing? | B23: =IF(B21=MAX($B$21:$F$21),"◄ MAX","") | C23: =IF(C21=MAX($B$21:$F$21),"◄ MAX","") | D23: =IF(D21=MAX($B$21:$F$21),"◄ MAX","") | E23: =IF(E21=MAX($B$21:$F$21),"◄ MAX","") | F23: =IF(F21=MAX($B$21:$F$21),"◄ MAX","")
A25: Winning column index | B25: =MATCH(MAX(OPT_PROFIT_RNG),OPT_PROFIT_RNG,0)
A27: Binding constraint, per crop, at the recommendation:
A28: BINDING_TOM | B28: =IF(REC_QTOM=MAXBED_TOM,"BED CAP",IF(REC_QTOM=STOP_TOM,"MC=PRICE","LABOR"))
A29: BINDING_CAR | B29: =IF(REC_QCAR=MAXBED_CAR,"BED CAP",IF(REC_QCAR=STOP_CAR,"MC=PRICE","LABOR"))
A30: BINDING_MES | B30: =IF(REC_QMES=MAXBED_MES,"BED CAP",IF(REC_QMES=STOP_MES,"MC=PRICE","LABOR"))
A32: MC_TOM last bed | B32: =IF(REC_QTOM=0,"n/a",INDEX(Labor!$D$7:$D$26,REC_QTOM))
A33: MC_CAR last bed | B33: =IF(REC_QCAR=0,"n/a",INDEX(Labor!$D$33:$D$52,REC_QCAR))
A34: MC_MES last bed | B34: =IF(REC_QMES=0,"n/a",INDEX(Labor!$D$59:$D$88,REC_QMES))
A36: BED_SHADOW_PRICE | B36: =IF(REC_BEDSUSED=TOTAL_BEDS,"binding — see Audit","0 (beds not binding)")

Sheet P&L
A1: P&L — recommended scenario, built independently from cash outlays
A2: Every figure here is computed from REC_* cells and Inputs directly — it does not reference Optimize!PROFIT. Validation rule 7 checks that the two totals agree.
A4: Decision
A5: N_TEMP (temps hired) | B5: =REC_NTEMP
A6: Q_TOM (beds) | B6: =REC_QTOM
A7: Q_CAR (beds) | B7: =REC_QCAR
A8: Q_MES (beds) | B8: =REC_QMES
A10: Revenue
A11: Tomatoes | B11: =REC_QTOM*PRICE_TOM
A12: Carrots | B12: =REC_QCAR*PRICE_CAR
A13: Mesclun | B13: =REC_QMES*PRICE_MES
A14: Total revenue | B14: =SUM(B11:B13)
A16: Variable costs
A17: Fertilizer — tomatoes | B17: =REC_QTOM*FERT_TOM
A18: Fertilizer — carrots | B18: =REC_QCAR*FERT_CAR
A19: Fertilizer — mesclun | B19: =REC_QMES*FERT_MES
A20: Total fertilizer | B20: =SUM(B17:B19)
A22: Labor cash cost
A23: Farmer salary (fixed, paid regardless) | B23: =FARMER_SALARY
A24: Temp wages (N_TEMP x TEMP_COST) | B24: =REC_NTEMP*TEMP_COST
A25: Total labor cash cost | B25: =B23+B24
A27: Fixed costs
A28: Fixed costs (season) | B28: =FIXED_COSTS
A30: PROFIT | B30: =B14-B20-B25-B28
A32: Reconciles to Optimize!PROFIT*? | B32: =IF(ROUND(B30-REC_PROFIT,2)=0,"PASS","FAIL")

Sheet Checks
A1: Checks — validation rules, run against the recommended scenario
A3: # | B3: Rule | C3: Result | D3: Note
A4: 1 | B4: BEDS_USED <= TOTAL_BEDS and each Q_c <= MAXBED_c | C4: =IF(AND(REC_BEDSUSED<=TOTAL_BEDS,REC_QTOM<=MAXBED_TOM,REC_QCAR<=MAXBED_CAR,REC_QMES<=MAXBED_MES),"PASS","FAIL")
A5: 2 | B5: LABOR_SLACK >= 0 at the chosen N_TEMP | C5: =IF(REC_LABORSLACK>=0,"PASS","FAIL")
A6: 3 | B6: LABOR_SLACK < TEMP_HRS (no temp paid for nothing) | C6: =IF(REC_LABORSLACK<TEMP_HRS,"PASS","FAIL")
A7: 4 | B7: Price-taker test — Tomatoes: MC(Q)<PRICE<=MC(Q+1) where the constraint isn't binding | C7: =IF(REC_QTOM=0,"n/a (0 beds)",IF(AND(REC_QTOM<MAXBED_TOM,REC_BEDSUSED<TOTAL_BEDS,REC_LABORSLACK>0),IF(AND(INDEX(Labor!$D$7:$D$26,REC_QTOM)<PRICE_TOM,PRICE_TOM<=INDEX(Labor!$D$7:$D$26,REC_QTOM+1)),"PASS","FAIL"),"n/a — at a binding constraint")) | D7: See Audit finding 2: this test is only meaningful when the crop stopped for its own MC=PRICE reason, not for lack of shared labor.
A8: 5 | B8: Price-taker test — Carrots | C8: =IF(REC_QCAR=0,"n/a (0 beds)",IF(AND(REC_QCAR<MAXBED_CAR,REC_BEDSUSED<TOTAL_BEDS,REC_LABORSLACK>0),IF(AND(INDEX(Labor!$D$33:$D$52,REC_QCAR)<PRICE_CAR,PRICE_CAR<=INDEX(Labor!$D$33:$D$52,REC_QCAR+1)),"PASS","FAIL"),"n/a — at a binding constraint")) | D8: Expected to read FAIL here as literally worded — carrots stop because labor runs out, not because the next bed is unprofitable. See Audit finding 2.
A9: 6 | B9: Price-taker test — Mesclun | C9: =IF(REC_QMES=0,"n/a (0 beds)",IF(AND(REC_QMES<MAXBED_MES,REC_BEDSUSED<TOTAL_BEDS,REC_LABORSLACK>0),IF(AND(INDEX(Labor!$D$59:$D$88,REC_QMES)<PRICE_MES,PRICE_MES<=INDEX(Labor!$D$59:$D$88,REC_QMES+1)),"PASS","FAIL"),"n/a — at a binding constraint")) | D9: Expected to read FAIL here as literally worded, for the same reason as Carrots. See Audit finding 2.
A10: 7 | B10: Constraint attribution — every crop's stopping point is traceable | C10: =IF(AND(Optimize!$B$28<>"",Optimize!$B$29<>"",Optimize!$B$30<>""),"PASS","FAIL") | D10: See Optimize sheet, BINDING_TOM/CAR/MES (rows 28-30).
A11: 8 | B11: Hand calculation — Tomatoes bed 10 vs. published check figures | D11: Three sub-checks below.
B12: LABOR_HRS_TOM(10) = 2,334.37 hrs | C12: =IF(ROUND(Labor!C16,2)=2334.37,"PASS","FAIL") | D12: Model value: see Labor!C16
B13: MARGINAL_LABOR_HRS_TOM(10) = 424.43 hrs | C13: =IF(ROUND(Labor!B16,2)=424.43,"PASS","FAIL") | D13: Model value: see Labor!B16
B14: MC_TOM(10) ≈ 8,248.59 | C14: =IF(ROUND(Labor!D16,2)=8248.59,"PASS","FAIL") | D14: Model value: see Labor!D16
A16: 9 | B16: Cash reconciliation — P&L PROFIT ties to Optimize PROFIT* | C16: ='P&L'!B32 | D16: See P&L sheet.
A17: 10 | B17: Hiring sweep — REC_PROFIT is the max across all 5 N_TEMP scenarios | C17: =IF(REC_PROFIT=MAX(OPT_PROFIT_RNG),"PASS","FAIL")
A18: 11 | B18: No hardcoded results outside Inputs and the Optimize decision cells | C18: Manual review | D18: Decision cells (Q_TOM/Q_CAR/Q_MES/N_TEMP on Optimize) are legitimately hardcoded — they are Solver's changing cells. Every other cell in Labor/Optimize/P&L is a formula.
A19: 12 | B19: No error values anywhere in the workbook | C19: =IF(SUMPRODUCT(--ISERROR(OPT_PROFIT_RNG))+SUMPRODUCT(--ISERROR(Labor!D7:D26))+SUMPRODUCT(--ISERROR(Labor!D33:D52))+SUMPRODUCT(--ISERROR(Labor!D59:D88))=0,"PASS","FAIL") | D19: Spot-checks the profit sweep and all three marginal-cost columns; confirm no errors elsewhere via recalc.
A21: Audit findings
A22: See the spec's own Audit findings section for the full narrative (FARMER_RATE bug, the price-taker test gap for Carrots/Mesclun, why a $/hour greedy ranking fails here, and the LibreOffice/Excel-automation substitution used to verify this workbook).
