Workbook
Name Total_Daily_Visitors: Model!$C$6
Name Percentage_Locals_Init: Model!$C$7
Name Total_Daily_AudioTour: Model!$C$8
Name AudioTour_Price: Model!$C$9
Name Local_AudioTour_Rate_Init: Model!$C$10
Name Local_AudioTour_Rate_PWYW: Model!$C$11
Name PWYW_Suggested_Price: Model!$C$12
Name PWYW_Payment_Ratio: Model!$C$13
Name Payment_Fade_Total: Model!$C$14
Name Fade_Timescale_Days: Model!$C$15
Name GiftShop_Net_Spend_Local: Model!$C$16
Name GiftShop_Spillover: Model!$C$17
Name Marketing_Spend: Model!$C$18
Name Locals_Share_Ceiling: Model!$C$19
Name Marketing_Saturation_Spend: Model!$C$20
Name Campaign_Days: Model!$C$21
Name Headset_Cost: Model!$C$22
Name Card_Fee_Rate: Model!$C$23
Name Card_Fee_Museum_Share: Model!$C$24
Name Device_Capacity: Model!$C$25
Name Device_Block_Size: Model!$C$26
Name Device_Block_Cost: Model!$C$27
Name Device_Amort_Days: Model!$C$28
Name Tourists_Base: Model!$C$31
Name Locals_Base: Model!$C$32
Name AudioLocal_Base: Model!$C$33
Name AudioTourist_Base: Model!$C$34
Name Fee_Keep: Model!$C$35
Name Average_PWYW_Start: Model!$C$36
Name Fade_Multiplier: Model!$C$37
Name Average_PWYW: Model!$C$38
Name Awareness: Model!$C$39
Name Percentage_Locals_Final: Model!$C$40

Sheet Model
B2: Pay-What-You-Want Audio Tour: Profitability Model
B3: Museum is free. Locals pay what they want for the audio tour (normally $7); tourists still pay $7. Yellow cells with blue text are inputs. Everything else recalculates.
B4: Structure: capabilities/economic-research/spec.md. PLACEHOLDER = not yet backed by a verified source; results that depend on one are only as good as that number.
B5: INPUTS (the named contract) | C5: Value | D5: Unit | F5: Source / status
B6: Total_Daily_Visitors | C6: 5000 | D6: people/day | F6: Spec: assumed.
B7: Percentage_Locals_Init | C7: 0.075 | D7: % of visitors | F7: You: 5-10%. Midpoint used.
B8: Total_Daily_AudioTour | C8: 250 | D8: people/day | F8: Spec: assumed. Includes the locals who already take the tour.
B9: AudioTour_Price | C9: 7 | D9: $ | F9: Spec (written there as Audio_Tour_Cost; this is the price tourists pay).
B10: Local_AudioTour_Rate_Init | C10: 0.1 | D10: % of locals | F10: You: 10% of locals take the audio tour today.
B11: Local_AudioTour_Rate_PWYW | C11: 0.2 | D11: % of locals | F11: PLACEHOLDER. You expect take-up to rise under PWYW. Test 10-50%.
B12: PWYW_Suggested_Price | C12: 7 | D12: $ | F12: Recommended price shown to locals.
B13: PWYW_Payment_Ratio | C13: 0.6 | D13: payment / suggested | F13: PLACEHOLDER. Day-1 average payment as a share of the suggested price, including $0 payers. Test 40-80%.
B14: Payment_Fade_Total | C14: 0.15 | D14: % decline | F14: PLACEHOLDER. Fall in the average payment from day 1 to the end of the campaign.
B15: Fade_Timescale_Days | C15: 30 | D15: days | F15: PLACEHOLDER. How fast the fade happens; the decline slows over time. Smaller = faster early drop.
B16: GiftShop_Net_Spend_Local | C16: 5 | D16: $/incremental local | F16: You: $5 or $10. Net contribution per NEW local visitor. See break-even below.
B17: GiftShop_Spillover | C17: 0 | D17: $/existing local | F17: PLACEHOLDER. Extra net spend by an aware existing local who takes the PWYW tour. 0 is conservative.
... B28: Device_Amort_Days | C28: 365 | D28: days | F28: You: amortize over one year. Only the campaign's share is charged here.
B30: DERIVED INPUTS
B31: Tourists_Base | C31: =Total_Daily_Visitors*(1-Percentage_Locals_Init) | F31: Total_Daily_Tourists in the spec.
B32: Locals_Base | C32: =Total_Daily_Visitors*Percentage_Locals_Init | F32: Total_Daily_Locals in the spec.
B33: AudioLocal_Base | C33: =Locals_Base*Local_AudioTour_Rate_Init | F33: Locals who take the tour today (and pay $7).
B34: AudioTourist_Base | C34: =Total_Daily_AudioTour-AudioLocal_Base | F34: Remainder of the 250 are tourists.
B35: Fee_Keep | C35: =1-Card_Fee_Rate*Card_Fee_Museum_Share | F35: Share of each local audio-tour payment the museum keeps after any card fee it bears.
B36: Average_PWYW_Start | C36: =PWYW_Suggested_Price*PWYW_Payment_Ratio | F36: Day-1 average payment per aware local audio-tour user.
B37: Fade_Multiplier | C37: =1-Payment_Fade_Total*((1-(Fade_Timescale_Days/Campaign_Days)*(1-EXP(-Campaign_Days/Fade_Timescale_Days)))/(1-EXP(-Campaign_Days/Fade_Timescale_Days))) | F37: Average of the fading payment over the campaign, as a share of day 1. Fade shape: 1 - e^(-t/timescale), scaled to reach the total decline on the last day.
B38: Average_PWYW | C38: =Average_PWYW_Start*Fade_Multiplier | F38: Campaign-average payment per aware local audio-tour user.
B39: Awareness | C39: =1-EXP(-Marketing_Spend/Marketing_Saturation_Spend) | F39: Share of the achievable marketing effect reached: 1 - e^(-spend / saturation). 0 at $0 spend. Also the share of existing locals who know PWYW exists.
B40: Percentage_Locals_Final | C40: =Percentage_Locals_Init+(Locals_Share_Ceiling-Percentage_Locals_Init)*Awareness | F40: Init + (ceiling - Init) x Awareness. Diminishing returns on marketing.
B42: DAILY VIEW (campaign average day) | C42: Baseline | D42: Campaign | E42: Change | F42: Notes
B43: Local visitors | C43: =Locals_Base | D43: =Tourists_Base*Percentage_Locals_Final/(1-Percentage_Locals_Final) | E43: =D43-C43 | F43: Final share is of ALL visitors, so locals = tourists x final / (1 - final). Tourists do not change.
B44: Tourist visitors | C44: =Tourists_Base | D44: =Tourists_Base | E44: =D44-C44
B45: Local share of visitors | C45: =Percentage_Locals_Init | D45: =Percentage_Locals_Final | E45: =D45-C45
B46: Local audio-tour users | C46: =AudioLocal_Base | D46: =Locals_Base*(1-Awareness)*Local_AudioTour_Rate_Init+(D43-Locals_Base*(1-Awareness))*Local_AudioTour_Rate_PWYW | E46: =D46-C46 | F46: Unaware existing locals behave as today (10%, pay $7). Aware locals, incl. all new ones, take the tour at the PWYW rate and pay Average_PWYW.
B47: Tourist audio-tour users | C47: =AudioTourist_Base | D47: =AudioTourist_Base | E47: =D47-C47 | F47: Tourists keep paying $7.
B48: Total audio-tour users | C48: =C46+C47 | D48: =D46+D47 | E48: =D48-C48
B49: Avg payment per local audio user ($) | C49: =AudioTour_Price | D49: =IF(D46=0,0,(Locals_Base*(1-Awareness)*Local_AudioTour_Rate_Init*AudioTour_Price+(D43-Locals_Base*(1-Awareness))*Local_AudioTour_Rate_PWYW*Average_PWYW)/D46) | E49: =D49-C49 | F49: Blend of unaware locals paying $7 and aware locals paying the campaign-average PWYW payment.
B50: Audio-tour revenue ($) | C50: =C46*C49+C47*AudioTour_Price | D50: =D46*D49+D47*AudioTour_Price | E50: =D50-C50 | F50: Change includes the $7 revenue lost when an aware existing local moves to PWYW.
B51: Card fee borne by museum ($) | C51: =-Card_Fee_Rate*Card_Fee_Museum_Share*C46*C49 | D51: =-Card_Fee_Rate*Card_Fee_Museum_Share*D46*D49 | E51: =D51-C51 | F51: On local audio-tour payments only. 0 while the customer pays the fee.
B52: Headset cost ($) | C52: =-C48*Headset_Cost | D52: =-D48*Headset_Cost | E52: =D52-C52 | F52: $1 per audio-tour user, including those who pay $0.
B53: Extra device blocks needed | C53: =MAX(0,ROUNDUP((C48-Device_Capacity)/Device_Block_Size,0)) | D53: =MAX(0,ROUNDUP((D48-Device_Capacity)/Device_Block_Size,0)) | E53: =D53-C53 | F53: Blocks of 25 above the 500 capacity.
...

Sheet Sensitivity
B2: Sensitivity Tables: Net Profit Over the Campaign
B3: Each table varies two levers; everything else comes from the Model tab. Axis values are editable. Green = profit, red = loss.
B5: 1. Marketing spend vs. gift shop spend per new local
B6: Marketing ($) \ Gift shop $ / new local | C6: 0 | D6: 1 | E6: 2.5 | F6: 5 | G6: 7.5 | H6: 10 | I6: 15
B7: 0 | C7: =Engine!R5 | D7: =Engine!R6 | E7: =Engine!R7 | F7: =Engine!R8 | G7: =Engine!R9 | H7: =Engine!R10 | I7: =Engine!R11
B8: 2500 | C8: =Engine!R12 | D8: =Engine!R13 | E8: =Engine!R14 | F8: =Engine!R15 | G8: =Engine!R16 | H8: =Engine!R17 | I8: =Engine!R18
B9: 5000 | C9: =Engine!R19 | D9: =Engine!R20 | E9: =Engine!R21 | F9: =Engine!R22 | G9: =Engine!R23 | H9: =Engine!R24 | I9: =Engine!R25
B10: 10000 | C10: =Engine!R26 | D10: =Engine!R27 | E10: =Engine!R28 | F10: =Engine!R29 | G10: =Engine!R30 | H10: =Engine!R31 | I10: =Engine!R32
B11: 15000 | C11: =Engine!R33 | D11: =Engine!R34 | E11: =Engine!R35 | F11: =Engine!R36 | G11: =Engine!R37 | H11: =Engine!R38 | I11: =Engine!R39
B12: 20000 | C12: =Engine!R40 | D12: =Engine!R41 | E12: =Engine!R42 | F12: =Engine!R43 | G12: =Engine!R44 | H12: =Engine!R45 | I12: =Engine!R46
B15: 2. Campaign-average payment vs. local take-up
B16: Avg payment ($) \ Take-up (% of locals) | C16: 0.1 | D16: 0.2 | E16: 0.3 | F16: 0.4 | G16: 0.5
B17: 0 | C17: =Engine!R47 | D17: =Engine!R48 | E17: =Engine!R49 | F17: =Engine!R50 | G17: =Engine!R51
B18: 1 | C18: =Engine!R52 | D18: =Engine!R53 | E18: =Engine!R54 | F18: =Engine!R55 | G18: =Engine!R56
B19: 2 | C19: =Engine!R57 | D19: =Engine!R58 | E19: =Engine!R59 | F19: =Engine!R60 | G19: =Engine!R61
B20: 3 | C20: =Engine!R62 | D20: =Engine!R63 | E20: =Engine!R64 | F20: =Engine!R65 | G20: =Engine!R66
B21: 4 | C21: =Engine!R67 | D21: =Engine!R68 | E21: =Engine!R69 | F21: =Engine!R70 | G21: =Engine!R71
B22: 5 | C22: =Engine!R72 | D22: =Engine!R73 | E22: =Engine!R74 | F22: =Engine!R75 | G22: =Engine!R76
B23: 6 | C23: =Engine!R77 | D23: =Engine!R78 | E23: =Engine!R79 | F23: =Engine!R80 | G23: =Engine!R81
B24: 7 | C24: =Engine!R82 | D24: =Engine!R83 | E24: =Engine!R84 | F24: =Engine!R85 | G24: =Engine!R86
B27: 3. Marketing spend vs. local traffic ceiling (7.5% = no draw)
B28: Marketing ($) \ Locals % of visitors (ceiling) | C28: 0.075 | D28: 0.09 | E28: 0.1 | F28: 0.125 | G28: 0.15 | H28: 0.2
B29: 0 | C29: =Engine!R87 | D29: =Engine!R88 | E29: =Engine!R89 | F29: =Engine!R90 | G29: =Engine!R91 | H29: =Engine!R92
B30: 2500 | C30: =Engine!R93 | D30: =Engine!R94 | E30: =Engine!R95 | F30: =Engine!R96 | G30: =Engine!R97 | H30: =Engine!R98
B31: 5000 | C31: =Engine!R99 | D31: =Engine!R100 | E31: =Engine!R101 | F31: =Engine!R102 | G31: =Engine!R103 | H31: =Engine!R104
B32: 10000 | C32: =Engine!R105 | D32: =Engine!R106 | E32: =Engine!R107 | F32: =Engine!R108 | G32: =Engine!R109 | H32: =Engine!R110
B33: 15000 | C33: =Engine!R111 | D33: =Engine!R112 | E33: =Engine!R113 | F33: =Engine!R114 | G33: =Engine!R115 | H33: =Engine!R116
B34: 20000 | C34: =Engine!R117 | D34: =Engine!R118 | E34: =Engine!R119 | F34: =Engine!R120 | G34: =Engine!R121 | H34: =Engine!R122
B37: 4. Local traffic ceiling vs. gift shop spend (base marketing)
B38: Locals % ceiling \ Gift shop $ / new local | C38: 0 | D38: 1 | E38: 2.5 | F38: 5 | G38: 7.5 | H38: 10 | I38: 15
B39: 0.075 | C39: =Engine!R123 | D39: =Engine!R124 | E39: =Engine!R125 | F39: =Engine!R126 | G39: =Engine!R127 | H39: =Engine!R128 | I39: =Engine!R129
B40: 0.09 | C40: =Engine!R130 | D40: =Engine!R131 | E40: =Engine!R132 | F40: =Engine!R133 | G40: =Engine!R134 | H40: =Engine!R135 | I40: =Engine!R136
B41: 0.1 | C41: =Engine!R137 | D41: =Engine!R138 | E41: =Engine!R139 | F41: =Engine!R140 | G41: =Engine!R141 | H41: =Engine!R142 | I41: =Engine!R143
B42: 0.125 | C42: =Engine!R144 | D42: =Engine!R145 | E42: =Engine!R146 | F42: =Engine!R147 | G42: =Engine!R148 | H42: =Engine!R149 | I42: =Engine!R150
B43: 0.15 | C43: =Engine!R151 | D43: =Engine!R152 | E43: =Engine!R153 | F43: =Engine!R154 | G43: =Engine!R155 | H43: =Engine!R156 | I43: =Engine!R157
B44: 0.2 | C44: =Engine!R158 | D44: =Engine!R159 | E44: =Engine!R160 | F44: =Engine!R161 | G44: =Engine!R162 | H44: =Engine!R163 | I44: =Engine!R164
B47: 5. Take-up and payment move together (base marketing)
B48: Scenario | C48: Payment ratio | D48: Take-up | E48: Avg payment ($) | F48: Net profit ($) | G48: Net profit, no gift shop ($)
B49: Payment-led: few take it, they pay well | C49: 0.8 | D49: 0.1 | E49: =PWYW_Suggested_Price*C49*Fade_Multiplier | F49: =Engine!R165 | G49: =Engine!R165-Engine!P165*Campaign_Days
B50: Balanced (near the base case) | C50: 0.6 | D50: 0.2 | E50: =PWYW_Suggested_Price*C50*Fade_Multiplier | F50: =Engine!R166 | G50: =Engine!R166-Engine!P166*Campaign_Days
...

Sheet Engine
A1: Scenario | B1: Marketing | C1: Ceiling | D1: GiftShop | E1: Avg PWYW | F1: Take-up | G1: Final share | H1: Local visitors | I1: Added locals | J1: Local audio users | K1: Total audio users | L1: Device blocks | M1: Device $/day | N1: Audio rev chg | O1: Headset chg | P1: Gift shop chg | Q1: Daily contribution | R1: Net profit | T1: One row per sensitivity scenario. Lever columns B-F come from the Sensitivity axes or the Model inputs.
A2: Base case | B2: =Marketing_Spend | C2: =Locals_Share_Ceiling | D2: =GiftShop_Net_Spend_Local | E2: =Average_PWYW | F2: =Local_AudioTour_Rate_PWYW | G2: =Percentage_Locals_Init+(C2-Percentage_Locals_Init)*(1-EXP(-B2/Marketing_Saturation_Spend)) | H2: =Tourists_Base*G2/(1-G2) | I2: =H2-Locals_Base | J2: =Locals_Base*(1-(1-EXP(-B2/Marketing_Saturation_Spend)))*Local_AudioTour_Rate_Init+(H2-Locals_Base*(1-(1-EXP(-B2/Marketing_Saturation_Spend))))*F2 | K2: =AudioTourist_Base+J2 | L2: =MAX(0,ROUNDUP((K2-Device_Capacity)/Device_Block_Size,0)) | M2: =L2*Device_Block_Cost/Device_Amort_Days | N2: =Fee_Keep*(Locals_Base*(1-(1-EXP(-B2/Marketing_Saturation_Spend)))*Local_AudioTour_Rate_Init*AudioTour_Price+(H2-Locals_Base*(1-(1-EXP(-B2/Marketing_Saturation_Spend))))*F2*E2-AudioLocal_Base*AudioTour_Price) | O2: =(K2-Total_Daily_AudioTour)*Headset_Cost | P2: =I2*D2+Locals_Base*(1-EXP(-B2/Marketing_Saturation_Spend))*F2*GiftShop_Spillover | Q2: =N2-O2-M2+P2 | R2: =Q2*Campaign_Days-B2
A3: Zero-marketing test | B3: =0 | C3: =Locals_Share_Ceiling | D3: =GiftShop_Net_Spend_Local | E3: =Average_PWYW | F3: =Local_AudioTour_Rate_PWYW | G3: =Percentage_Locals_Init+(C3-Percentage_Locals_Init)*(1-EXP(-B3/Marketing_Saturation_Spend)) | H3: =Tourists_Base*G3/(1-G3) | I3: =H3-Locals_Base | J3: =Locals_Base*(1-(1-EXP(-B3/Marketing_Saturation_Spend)))*Local_AudioTour_Rate_Init+(H3-Locals_Base*(1-(1-EXP(-B3/Marketing_Saturation_Spend))))*F3 | K3: =AudioTourist_Base+J3 | L3: =MAX(0,ROUNDUP((K3-Device_Capacity)/Device_Block_Size,0)) | M3: =L3*Device_Block_Cost/Device_Amort_Days | N3: =Fee_Keep*(Locals_Base*(1-(1-EXP(-B3/Marketing_Saturation_Spend)))*Local_AudioTour_Rate_Init*AudioTour_Price+(H3-Locals_Base*(1-(1-EXP(-B3/Marketing_Saturation_Spend))))*F3*E3-AudioLocal_Base*AudioTour_Price) | O3: =(K3-Total_Daily_AudioTour)*Headset_Cost | P3: =I3*D3+Locals_Base*(1-EXP(-B3/Marketing_Saturation_Spend))*F3*GiftShop_Spillover | Q3: =N3-O3-M3+P3 | R3: =Q3*Campaign_Days-B3
A4: Break-even draw test | B4: =Marketing_Spend | C4: =IF(AND(ISNUMBER(Model!$C$76),Awareness>0),Percentage_Locals_Init+((Locals_Base+Model!$C$76)/(Tourists_Base+Locals_Base+Model!$C$76)-Percentage_Locals_Init)/Awareness,Locals_Share_Ceiling) | D4: =GiftShop_Net_Spend_Local | E4: =Average_PWYW | F4: =Local_AudioTour_Rate_PWYW | G4: =Percentage_Locals_Init+(C4-Percentage_Locals_Init)*(1-EXP(-B4/Marketing_Saturation_Spend)) | H4: =Tourists_Base*G4/(1-G4) | I4: =H4-Locals_Base | J4: =Locals_Base*(1-(1-EXP(-B4/Marketing_Saturation_Spend)))*Local_AudioTour_Rate_Init+(H4-Locals_Base*(1-(1-EXP(-B4/Marketing_Saturation_Spend))))*F4 | K4: =AudioTourist_Base+J4 | L4: =MAX(0,ROUNDUP((K4-Device_Capacity)/Device_Block_Size,0)) | M4: =L4*Device_Block_Cost/Device_Amort_Days | N4: =Fee_Keep*(Locals_Base*(1-(1-EXP(-B4/Marketing_Saturation_Spend)))*Local_AudioTour_Rate_Init*AudioTour_Price+(H4-Locals_Base*(1-(1-EXP(-B4/Marketing_Saturation_Spend))))*F4*E4-AudioLocal_Base*AudioTour_Price) | O4: =(K4-Total_Daily_AudioTour)*Headset_Cost | P4: =I4*D4+Locals_Base*(1-EXP(-B4/Marketing_Saturation_Spend))*F4*GiftShop_Spillover | Q4: =N4-O4-M4+P4 | R4: =Q4*Campaign_Days-B4
A5: 1. r1 c1 | B5: =Sensitivity!$B$7 | C5: =Locals_Share_Ceiling | D5: =Sensitivity!C$6 | E5: =Average_PWYW | F5: =Local_AudioTour_Rate_PWYW | G5: =Percentage_Locals_Init+(C5-Percentage_Locals_Init)*(1-EXP(-B5/Marketing_Saturation_Spend)) | H5: =Tourists_Base*G5/(1-G5) | I5: =H5-Locals_Base | J5: =Locals_Base*(1-(1-EXP(-B5/Marketing_Saturation_Spend)))*Local_AudioTour_Rate_Init+(H5-Locals_Base*(1-(1-EXP(-B5/Marketing_Saturation_Spend))))*F5 | K5: =AudioTourist_Base+J5 | L5: =MAX(0,ROUNDUP((K5-Device_Capacity)/Device_Block_Size,0)) | M5: =L5*Device_Block_Cost/Device_Amort_Days | N5: =Fee_Keep*(Locals_Base*(1-(1-EXP(-B5/Marketing_Saturation_Spend)))*Local_AudioTour_Rate_Init*AudioTour_Price+(H5-Locals_Base*(1-(1-EXP(-B5/Marketing_Saturation_Spend))))*F5*E5-AudioLocal_Base*AudioTour_Price) | O5: =(K5-Total_Daily_AudioTour)*Headset_Cost | P5: =I5*D5+Locals_Base*(1-EXP(-B5/Marketing_Saturation_Spend))*F5*GiftShop_Spillover | Q5: =N5-O5-M5+P5 | R5: =Q5*Campaign_Days-B5
A6: 1. r1 c2 | B6: =Sensitivity!$B$7 | C6: =Locals_Share_Ceiling | D6: =Sensitivity!D$6 | E6: =Average_PWYW | F6: =Local_AudioTour_Rate_PWYW | G6: =Percentage_Locals_Init+(C6-Percentage_Locals_Init)*(1-EXP(-B6/Marketing_Saturation_Spend)) | H6: =Tourists_Base*G6/(1-G6) | I6: =H6-Locals_Base | J6: =Locals_Base*(1-(1-EXP(-B6/Marketing_Saturation_Spend)))*Local_AudioTour_Rate_Init+(H6-Locals_Base*(1-(1-EXP(-B6/Marketing_Saturation_Spend))))*F6 | K6: =AudioTourist_Base+J6 | L6: =MAX(0,ROUNDUP((K6-Device_Capacity)/Device_Block_Size,0)) | M6: =L6*Device_Block_Cost/Device_Amort_Days | N6: =Fee_Keep*(Locals_Base*(1-(1-EXP(-B6/Marketing_Saturation_Spend)))*Local_AudioTour_Rate_Init*AudioTour_Price+(H6-Locals_Base*(1-(1-EXP(-B6/Marketing_Saturation_Spend))))*F6*E6-AudioLocal_Base*AudioTour_Price) | O6: =(K6-Total_Daily_AudioTour)*Headset_Cost | P6: =I6*D6+Locals_Base*(1-EXP(-B6/Marketing_Saturation_Spend))*F6*GiftShop_Spillover | Q6: =N6-O6-M6+P6 | R6: =Q6*Campaign_Days-B6
A7: 1. r1 c3 | B7: =Sensitivity!$B$7 | C7: =Locals_Share_Ceiling | D7: =Sensitivity!E$6 | E7: =Average_PWYW | F7: =Local_AudioTour_Rate_PWYW | G7: =Percentage_Locals_Init+(C7-Percentage_Locals_Init)*(1-EXP(-B7/Marketing_Saturation_Spend)) | H7: =Tourists_Base*G7/(1-G7) | I7: =H7-Locals_Base | J7: =Locals_Base*(1-(1-EXP(-B7/Marketing_Saturation_Spend)))*Local_AudioTour_Rate_Init+(H7-Locals_Base*(1-(1-EXP(-B7/Marketing_Saturation_Spend))))*F7 | K7: =AudioTourist_Base+J7 | L7: =MAX(0,ROUNDUP((K7-Device_Capacity)/Device_Block_Size,0)) | M7: =L7*Device_Block_Cost/Device_Amort_Days | N7: =Fee_Keep*(Locals_Base*(1-(1-EXP(-B7/Marketing_Saturation_Spend)))*Local_AudioTour_Rate_Init*AudioTour_Price+(H7-Locals_Base*(1-(1-EXP(-B7/Marketing_Saturation_Spend))))*F7*E7-AudioLocal_Base*AudioTour_Price) | O7: =(K7-Total_Daily_AudioTour)*Headset_Cost | P7: =I7*D7+Locals_Base*(1-EXP(-B7/Marketing_Saturation_Spend))*F7*GiftShop_Spillover | Q7: =N7-O7-M7+P7 | R7: =Q7*Campaign_Days-B7
A8: 1. r1 c4 | B8: =Sensitivity!$B$7 | C8: =Locals_Share_Ceiling | D8: =Sensitivity!F$6 | E8: =Average_PWYW | F8: =Local_AudioTour_Rate_PWYW | G8: =Percentage_Locals_Init+(C8-Percentage_Locals_Init)*(1-EXP(-B8/Marketing_Saturation_Spend)) | H8: =Tourists_Base*G8/(1-G8) | I8: =H8-Locals_Base | J8: =Locals_Base*(1-(1-EXP(-B8/Marketing_Saturation_Spend)))*Local_AudioTour_Rate_Init+(H8-Locals_Base*(1-(1-EXP(-B8/Marketing_Saturation_Spend))))*F8 | K8: =AudioTourist_Base+J8 | L8: =MAX(0,ROUNDUP((K8-Device_Capacity)/Device_Block_Size,0)) | M8: =L8*Device_Block_Cost/Device_Amort_Days | N8: =Fee_Keep*(Locals_Base*(1-(1-EXP(-B8/Marketing_Saturation_Spend)))*Local_AudioTour_Rate_Init*AudioTour_Price+(H8-Locals_Base*(1-(1-EXP(-B8/Marketing_Saturation_Spend))))*F8*E8-AudioLocal_Base*AudioTour_Price) | O8: =(K8-Total_Daily_AudioTour)*Headset_Cost | P8: =I8*D8+Locals_Base*(1-EXP(-B8/Marketing_Saturation_Spend))*F8*GiftShop_Spillover | Q8: =N8-O8-M8+P8 | R8: =Q8*Campaign_Days-B8
A9: 1. r1 c5 | B9: =Sensitivity!$B$7 | C9: =Locals_Share_Ceiling | D9: =Sensitivity!G$6 | E9: =Average_PWYW | F9: =Local_AudioTour_Rate_PWYW | G9: =Percentage_Locals_Init+(C9-Percentage_Locals_Init)*(1-EXP(-B9/Marketing_Saturation_Spend)) | H9: =Tourists_Base*G9/(1-G9) | I9: =H9-Locals_Base | J9: =Locals_Base*(1-(1-EXP(-B9/Marketing_Saturation_Spend)))*Local_AudioTour_Rate_Init+(H9-Locals_Base*(1-(1-EXP(-B9/Marketing_Saturation_Spend))))*F9 | K9: =AudioTourist_Base+J9 | L9: =MAX(0,ROUNDUP((K9-Device_Capacity)/Device_Block_Size,0)) | M9: =L9*Device_Block_Cost/Device_Amort_Days | N9: =Fee_Keep*(Locals_Base*(1-(1-EXP(-B9/Marketing_Saturation_Spend)))*Local_AudioTour_Rate_Init*AudioTour_Price+(H9-Locals_Base*(1-(1-EXP(-B9/Marketing_Saturation_Spend))))*F9*E9-AudioLocal_Base*AudioTour_Price) | O9: =(K9-Total_Daily_AudioTour)*Headset_Cost | P9: =I9*D9+Locals_Base*(1-EXP(-B9/Marketing_Saturation_Spend))*F9*GiftShop_Spillover | Q9: =N9-O9-M9+P9 | R9: =Q9*Campaign_Days-B9
A10: 1. r1 c6 | B10: =Sensitivity!$B$7 | C10: =Locals_Share_Ceiling | D10: =Sensitivity!H$6 | E10: =Average_PWYW | F10: =Local_AudioTour_Rate_PWYW | G10: =Percentage_Locals_Init+(C10-Percentage_Locals_Init)*(1-EXP(-B10/Marketing_Saturation_Spend)) | H10: =Tourists_Base*G10/(1-G10) | I10: =H10-Locals_Base | J10: =Locals_Base*(1-(1-EXP(-B10/Marketing_Saturation_Spend)))*Local_AudioTour_Rate_Init+(H10-Locals_Base*(1-(1-EXP(-B10/Marketing_Saturation_Spend))))*F10 | K10: =AudioTourist_Base+J10 | L10: =MAX(0,ROUNDUP((K10-Device_Capacity)/Device_Block_Size,0)) | M10: =L10*Device_Block_Cost/Device_Amort_Days | N10: =Fee_Keep*(Locals_Base*(1-(1-EXP(-B10/Marketing_Saturation_Spend)))*Local_AudioTour_Rate_Init*AudioTour_Price+(H10-Locals_Base*(1-(1-EXP(-B10/Marketing_Saturation_Spend))))*F10*E10-AudioLocal_Base*AudioTour_Price) | O10: =(K10-Total_Daily_AudioTour)*Headset_Cost | P10: =I10*D10+Locals_Base*(1-EXP(-B10/Marketing_Saturation_Spend))*F10*GiftShop_Spillover | Q10: =N10-O10-M10+P10 | R10: =Q10*Campaign_Days-B10
A11: 1. r1 c7 | B11: =Sensitivity!$B$7 | C11: =Locals_Share_Ceiling | D11: =Sensitivity!I$6 | E11: =Average_PWYW | F11: =Local_AudioTour_Rate_PWYW | G11: =Percentage_Locals_Init+(C11-Percentage_Locals_Init)*(1-EXP(-B11/Marketing_Saturation_Spend)) | H11: =Tourists_Base*G11/(1-G11) | I11: =H11-Locals_Base | J11: =Locals_Base*(1-(1-EXP(-B11/Marketing_Saturation_Spend)))*Local_AudioTour_Rate_Init+(H11-Locals_Base*(1-(1-EXP(-B11/Marketing_Saturation_Spend))))*F11 | K11: =AudioTourist_Base+J11 | L11: =MAX(0,ROUNDUP((K11-Device_Capacity)/Device_Block_Size,0)) | M11: =L11*Device_Block_Cost/Device_Amort_Days | N11: =Fee_Keep*(Locals_Base*(1-(1-EXP(-B11/Marketing_Saturation_Spend)))*Local_AudioTour_Rate_Init*AudioTour_Price+(H11-Locals_Base*(1-(1-EXP(-B11/Marketing_Saturation_Spend))))*F11*E11-AudioLocal_Base*AudioTour_Price) | O11: =(K11-Total_Daily_AudioTour)*Headset_Cost | P11: =I11*D11+Locals_Base*(1-EXP(-B11/Marketing_Saturation_Spend))*F11*GiftShop_Spillover | Q11: =N11-O11-M11+P11 | R11: =Q11*Campaign_Days-B11
A12: 1. r2 c1 | B12: =Sensitivity!$B$8 | C12: =Locals_Share_Ceiling | D12: =Sensitivity!C$6 | E12: =Average_PWYW | F12: =Local_AudioTour_Rate_PWYW | G12: =Percentage_Locals_Init+(C12-Percentage_Locals_Init)*(1-EXP(-B12/Marketing_Saturation_Spend)) | H12: =Tourists_Base*G12/(1-G12) | I12: =H12-Locals_Base | J12: =Locals_Base*(1-(1-EXP(-B12/Marketing_Saturation_Spend)))*Local_AudioTour_Rate_Init+(H12-Locals_Base*(1-(1-EXP(-B12/Marketing_Saturation_Spend))))*F12 | K12: =AudioTourist_Base+J12 | L12: =MAX(0,ROUNDUP((K12-Device_Capacity)/Device_Block_Size,0)) | M12: =L12*Device_Block_Cost/Device_Amort_Days | N12: =Fee_Keep*(Locals_Base*(1-(1-EXP(-B12/Marketing_Saturation_Spend)))*Local_AudioTour_Rate_Init*AudioTour_Price+(H12-Locals_Base*(1-(1-EXP(-B12/Marketing_Saturation_Spend))))*F12*E12-AudioLocal_Base*AudioTour_Price) | O12: =(K12-Total_Daily_AudioTour)*Headset_Cost | P12: =I12*D12+Locals_Base*(1-EXP(-B12/Marketing_Saturation_Spend))*F12*GiftShop_Spillover | Q12: =N12-O12-M12+P12 | R12: =Q12*Campaign_Days-B12
A13: 1. r2 c2 | B13: =Sensitivity!$B$8 | C13: =Locals_Share_Ceiling | D13: =Sensitivity!D$6 | E13: =Average_PWYW | F13: =Local_AudioTour_Rate_PWYW | G13: =Percentage_Locals_Init+(C13-Percentage_Locals_Init)*(1-EXP(-B13/Marketing_Saturation_Spend)) | H13: =Tourists_Base*G13/(1-G13) | I13: =H13-Locals_Base | J13: =Locals_Base*(1-(1-EXP(-B13/Marketing_Saturation_Spend)))*Local_AudioTour_Rate_Init+(H13-Locals_Base*(1-(1-EXP(-B13/Marketing_Saturation_Spend))))*F13 | K13: =AudioTourist_Base+J13 | L13: =MAX(0,ROUNDUP((K13-Device_Capacity)/Device_Block_Size,0)) | M13: =L13*Device_Block_Cost/Device_Amort_Days | N13: =Fee_Keep*(Locals_Base*(1-(1-EXP(-B13/Marketing_Saturation_Spend)))*Local_AudioTour_Rate_Init*AudioTour_Price+(H13-Locals_Base*(1-(1-EXP(-B13/Marketing_Saturation_Spend))))*F13*E13-AudioLocal_Base*AudioTour_Price) | O13: =(K13-Total_Daily_AudioTour)*Headset_Cost | P13: =I13*D13+Locals_Base*(1-EXP(-B13/Marketing_Saturation_Spend))*F13*GiftShop_Spillover | Q13: =N13-O13-M13+P13 | R13: =Q13*Campaign_Days-B13
A14: 1. r2 c3 | B14: =Sensitivity!$B$8 | C14: =Locals_Share_Ceiling | D14: =Sensitivity!E$6 | E14: =Average_PWYW | F14: =Local_AudioTour_Rate_PWYW | G14: =Percentage_Locals_Init+(C14-Percentage_Locals_Init)*(1-EXP(-B14/Marketing_Saturation_Spend)) | H14: =Tourists_Base*G14/(1-G14) | I14: =H14-Locals_Base | J14: =Locals_Base*(1-(1-EXP(-B14/Marketing_Saturation_Spend)))*Local_AudioTour_Rate_Init+(H14-Locals_Base*(1-(1-EXP(-B14/Marketing_Saturation_Spend))))*F14 | K14: =AudioTourist_Base+J14 | L14: =MAX(0,ROUNDUP((K14-Device_Capacity)/Device_Block_Size,0)) | M14: =L14*Device_Block_Cost/Device_Amort_Days | N14: =Fee_Keep*(Locals_Base*(1-(1-EXP(-B14/Marketing_Saturation_Spend)))*Local_AudioTour_Rate_Init*AudioTour_Price+(H14-Locals_Base*(1-(1-EXP(-B14/Marketing_Saturation_Spend))))*F14*E14-AudioLocal_Base*AudioTour_Price) | O14: =(K14-Total_Daily_AudioTour)*Headset_Cost | P14: =I14*D14+Locals_Base*(1-EXP(-B14/Marketing_Saturation_Spend))*F14*GiftShop_Spillover | Q14: =N14-O14-M14+P14 | R14: =Q14*Campaign_Days-B14
A15: 1. r2 c4 | B15: =Sensitivity!$B$8 | C15: =Locals_Share_Ceiling | D15: =Sensitivity!F$6 | E15: =Average_PWYW | F15: =Local_AudioTour_Rate_PWYW | G15: =Percentage_Locals_Init+(C15-Percentage_Locals_Init)*(1-EXP(-B15/Marketing_Saturation_Spend)) | H15: =Tourists_Base*G15/(1-G15) | I15: =H15-Locals_Base | J15: =Locals_Base*(1-(1-EXP(-B15/Marketing_Saturation_Spend)))*Local_AudioTour_Rate_Init+(H15-Locals_Base*(1-(1-EXP(-B15/Marketing_Saturation_Spend))))*F15 | K15: =AudioTourist_Base+J15 | L15: =MAX(0,ROUNDUP((K15-Device_Capacity)/Device_Block_Size,0)) | M15: =L15*Device_Block_Cost/Device_Amort_Days | N15: =Fee_Keep*(Locals_Base*(1-(1-EXP(-B15/Marketing_Saturation_Spend)))*Local_AudioTour_Rate_Init*AudioTour_Price+(H15-Locals_Base*(1-(1-EXP(-B15/Marketing_Saturation_Spend))))*F15*E15-AudioLocal_Base*AudioTour_Price) | O15: =(K15-Total_Daily_AudioTour)*Headset_Cost | P15: =I15*D15+Locals_Base*(1-EXP(-B15/Marketing_Saturation_Spend))*F15*GiftShop_Spillover | Q15: =N15-O15-M15+P15 | R15: =Q15*Campaign_Days-B15
A16: 1. r2 c5 | B16: =Sensitivity!$B$8 | C16: =Locals_Share_Ceiling | D16: =Sensitivity!G$6 | E16: =Average_PWYW | F16: =Local_AudioTour_Rate_PWYW | G16: =Percentage_Locals_Init+(C16-Percentage_Locals_Init)*(1-EXP(-B16/Marketing_Saturation_Spend)) | H16: =Tourists_Base*G16/(1-G16) | I16: =H16-Locals_Base | J16: =Locals_Base*(1-(1-EXP(-B16/Marketing_Saturation_Spend)))*Local_AudioTour_Rate_Init+(H16-Locals_Base*(1-(1-EXP(-B16/Marketing_Saturation_Spend))))*F16 | K16: =AudioTourist_Base+J16 | L16: =MAX(0,ROUNDUP((K16-Device_Capacity)/Device_Block_Size,0)) | M16: =L16*Device_Block_Cost/Device_Amort_Days | N16: =Fee_Keep*(Locals_Base*(1-(1-EXP(-B16/Marketing_Saturation_Spend)))*Local_AudioTour_Rate_Init*AudioTour_Price+(H16-Locals_Base*(1-(1-EXP(-B16/Marketing_Saturation_Spend))))*F16*E16-AudioLocal_Base*AudioTour_Price) | O16: =(K16-Total_Daily_AudioTour)*Headset_Cost | P16: =I16*D16+Locals_Base*(1-EXP(-B16/Marketing_Saturation_Spend))*F16*GiftShop_Spillover | Q16: =N16-O16-M16+P16 | R16: =Q16*Campaign_Days-B16
A17: 1. r2 c6 | B17: =Sensitivity!$B$8 | C17: =Locals_Share_Ceiling | D17: =Sensitivity!H$6 | E17: =Average_PWYW | F17: =Local_AudioTour_Rate_PWYW | G17: =Percentage_Locals_Init+(C17-Percentage_Locals_Init)*(1-EXP(-B17/Marketing_Saturation_Spend)) | H17: =Tourists_Base*G17/(1-G17) | I17: =H17-Locals_Base | J17: =Locals_Base*(1-(1-EXP(-B17/Marketing_Saturation_Spend)))*Local_AudioTour_Rate_Init+(H17-Locals_Base*(1-(1-EXP(-B17/Marketing_Saturation_Spend))))*F17 | K17: =AudioTourist_Base+J17 | L17: =MAX(0,ROUNDUP((K17-Device_Capacity)/Device_Block_Size,0)) | M17: =L17*Device_Block_Cost/Device_Amort_Days | N17: =Fee_Keep*(Locals_Base*(1-(1-EXP(-B17/Marketing_Saturation_Spend)))*Local_AudioTour_Rate_Init*AudioTour_Price+(H17-Locals_Base*(1-(1-EXP(-B17/Marketing_Saturation_Spend))))*F17*E17-AudioLocal_Base*AudioTour_Price) | O17: =(K17-Total_Daily_AudioTour)*Headset_Cost | P17: =I17*D17+Locals_Base*(1-EXP(-B17/Marketing_Saturation_Spend))*F17*GiftShop_Spillover | Q17: =N17-O17-M17+P17 | R17: =Q17*Campaign_Days-B17
A18: 1. r2 c7 | B18: =Sensitivity!$B$8 | C18: =Locals_Share_Ceiling | D18: =Sensitivity!I$6 | E18: =Average_PWYW | F18: =Local_AudioTour_Rate_PWYW | G18: =Percentage_Locals_Init+(C18-Percentage_Locals_Init)*(1-EXP(-B18/Marketing_Saturation_Spend)) | H18: =Tourists_Base*G18/(1-G18) | I18: =H18-Locals_Base | J18: =Locals_Base*(1-(1-EXP(-B18/Marketing_Saturation_Spend)))*Local_AudioTour_Rate_Init+(H18-Locals_Base*(1-(1-EXP(-B18/Marketing_Saturation_Spend))))*F18 | K18: =AudioTourist_Base+J18 | L18: =MAX(0,ROUNDUP((K18-Device_Capacity)/Device_Block_Size,0)) | M18: =L18*Device_Block_Cost/Device_Amort_Days | N18: =Fee_Keep*(Locals_Base*(1-(1-EXP(-B18/Marketing_Saturation_Spend)))*Local_AudioTour_Rate_Init*AudioTour_Price+(H18-Locals_Base*(1-(1-EXP(-B18/Marketing_Saturation_Spend))))*F18*E18-AudioLocal_Base*AudioTour_Price) | O18: =(K18-Total_Daily_AudioTour)*Headset_Cost | P18: =I18*D18+Locals_Base*(1-EXP(-B18/Marketing_Saturation_Spend))*F18*GiftShop_Spillover | Q18: =N18-O18-M18+P18 | R18: =Q18*Campaign_Days-B18
A19: 1. r3 c1 | B19: =Sensitivity!$B$9 | C19: =Locals_Share_Ceiling | D19: =Sensitivity!C$6 | E19: =Average_PWYW | F19: =Local_AudioTour_Rate_PWYW | G19: =Percentage_Locals_Init+(C19-Percentage_Locals_Init)*(1-EXP(-B19/Marketing_Saturation_Spend)) | H19: =Tourists_Base*G19/(1-G19) | I19: =H19-Locals_Base | J19: =Locals_Base*(1-(1-EXP(-B19/Marketing_Saturation_Spend)))*Local_AudioTour_Rate_Init+(H19-Locals_Base*(1-(1-EXP(-B19/Marketing_Saturation_Spend))))*F19 | K19: =AudioTourist_Base+J19 | L19: =MAX(0,ROUNDUP((K19-Device_Capacity)/Device_Block_Size,0)) | M19: =L19*Device_Block_Cost/Device_Amort_Days | N19: =Fee_Keep*(Locals_Base*(1-(1-EXP(-B19/Marketing_Saturation_Spend)))*Local_AudioTour_Rate_Init*AudioTour_Price+(H19-Locals_Base*(1-(1-EXP(-B19/Marketing_Saturation_Spend))))*F19*E19-AudioLocal_Base*AudioTour_Price) | O19: =(K19-Total_Daily_AudioTour)*Headset_Cost | P19: =I19*D19+Locals_Base*(1-EXP(-B19/Marketing_Saturation_Spend))*F19*GiftShop_Spillover | Q19: =N19-O19-M19+P19 | R19: =Q19*Campaign_Days-B19
A20: 1. r3 c2 | B20: =Sensitivity!$B$9 | C20: =Locals_Share_Ceiling | D20: =Sensitivity!D$6 | E20: =Average_PWYW | F20: =Local_AudioTour_Rate_PWYW | G20: =Percentage_Locals_Init+(C20-Percentage_Locals_Init)*(1-EXP(-B20/Marketing_Saturation_Spend)) | H20: =Tourists_Base*G20/(1-G20) | I20: =H20-Locals_Base | J20: =Locals_Base*(1-(1-EXP(-B20/Marketing_Saturation_Spend)))*Local_AudioTour_Rate_Init+(H20-Locals_Base*(1-(1-EXP(-B20/Marketing_Saturation_Spend))))*F20 | K20: =AudioTourist_Base+J20 | L20: =MAX(0,ROUNDUP((K20-Device_Capacity)/Device_Block_Size,0)) | M20: =L20*Device_Block_Cost/Device_Amort_Days | N20: =Fee_Keep*(Locals_Base*(1-(1-EXP(-B20/Marketing_Saturation_Spend)))*Local_AudioTour_Rate_Init*AudioTour_Price+(H20-Locals_Base*(1-(1-EXP(-B20/Marketing_Saturation_Spend))))*F20*E20-AudioLocal_Base*AudioTour_Price) | O20: =(K20-Total_Daily_AudioTour)*Headset_Cost | P20: =I20*D20+Locals_Base*(1-EXP(-B20/Marketing_Saturation_Spend))*F20*GiftShop_Spillover | Q20: =N20-O20-M20+P20 | R20: =Q20*Campaign_Days-B20
A21: 1. r3 c3 | B21: =Sensitivity!$B$9 | C21: =Locals_Share_Ceiling | D21: =Sensitivity!E$6 | E21: =Average_PWYW | F21: =Local_AudioTour_Rate_PWYW | G21: =Percentage_Locals_Init+(C21-Percentage_Locals_Init)*(1-EXP(-B21/Marketing_Saturation_Spend)) | H21: =Tourists_Base*G21/(1-G21) | I21: =H21-Locals_Base | J21: =Locals_Base*(1-(1-EXP(-B21/Marketing_Saturation_Spend)))*Local_AudioTour_Rate_Init+(H21-Locals_Base*(1-(1-EXP(-B21/Marketing_Saturation_Spend))))*F21 | K21: =AudioTourist_Base+J21 | L21: =MAX(0,ROUNDUP((K21-Device_Capacity)/Device_Block_Size,0)) | M21: =L21*Device_Block_Cost/Device_Amort_Days | N21: =Fee_Keep*(Locals_Base*(1-(1-EXP(-B21/Marketing_Saturation_Spend)))*Local_AudioTour_Rate_Init*AudioTour_Price+(H21-Locals_Base*(1-(1-EXP(-B21/Marketing_Saturation_Spend))))*F21*E21-AudioLocal_Base*AudioTour_Price) | O21: =(K21-Total_Daily_AudioTour)*Headset_Cost | P21: =I21*D21+Locals_Base*(1-EXP(-B21/Marketing_Saturation_Spend))*F21*GiftShop_Spillover | Q21: =N21-O21-M21+P21 | R21: =Q21*Campaign_Days-B21
A22: 1. r3 c4 | B22: =Sensitivity!$B$9 | C22: =Locals_Share_Ceiling | D22: =Sensitivity!F$6 | E22: =Average_PWYW | F22: =Local_AudioTour_Rate_PWYW | G22: =Percentage_Locals_Init+(C22-Percentage_Locals_Init)*(1-EXP(-B22/Marketing_Saturation_Spend)) | H22: =Tourists_Base*G22/(1-G22) | I22: =H22-Locals_Base | J22: =Locals_Base*(1-(1-EXP(-B22/Marketing_Saturation_Spend)))*Local_AudioTour_Rate_Init+(H22-Locals_Base*(1-(1-EXP(-B22/Marketing_Saturation_Spend))))*F22 | K22: =AudioTourist_Base+J22 | L22: =MAX(0,ROUNDUP((K22-Device_Capacity)/Device_Block_Size,0)) | M22: =L22*Device_Block_Cost/Device_Amort_Days | N22: =Fee_Keep*(Locals_Base*(1-(1-EXP(-B22/Marketing_Saturation_Spend)))*Local_AudioTour_Rate_Init*AudioTour_Price+(H22-Locals_Base*(1-(1-EXP(-B22/Marketing_Saturation_Spend))))*F22*E22-AudioLocal_Base*AudioTour_Price) | O22: =(K22-Total_Daily_AudioTour)*Headset_Cost | P22: =I22*D22+Locals_Base*(1-EXP(-B22/Marketing_Saturation_Spend))*F22*GiftShop_Spillover | Q22: =N22-O22-M22+P22 | R22: =Q22*Campaign_Days-B22
A23: 1. r3 c5 | B23: =Sensitivity!$B$9 | C23: =Locals_Share_Ceiling | D23: =Sensitivity!G$6 | E23: =Average_PWYW | F23: =Local_AudioTour_Rate_PWYW | G23: =Percentage_Locals_Init+(C23-Percentage_Locals_Init)*(1-EXP(-B23/Marketing_Saturation_Spend)) | H23: =Tourists_Base*G23/(1-G23) | I23: =H23-Locals_Base | J23: =Locals_Base*(1-(1-EXP(-B23/Marketing_Saturation_Spend)))*Local_AudioTour_Rate_Init+(H23-Locals_Base*(1-(1-EXP(-B23/Marketing_Saturation_Spend))))*F23 | K23: =AudioTourist_Base+J23 | L23: =MAX(0,ROUNDUP((K23-Device_Capacity)/Device_Block_Size,0)) | M23: =L23*Device_Block_Cost/Device_Amort_Days | N23: =Fee_Keep*(Locals_Base*(1-(1-EXP(-B23/Marketing_Saturation_Spend)))*Local_AudioTour_Rate_Init*AudioTour_Price+(H23-Locals_Base*(1-(1-EXP(-B23/Marketing_Saturation_Spend))))*F23*E23-AudioLocal_Base*AudioTour_Price) | O23: =(K23-Total_Daily_AudioTour)*Headset_Cost | P23: =I23*D23+Locals_Base*(1-EXP(-B23/Marketing_Saturation_Spend))*F23*GiftShop_Spillover | Q23: =N23-O23-M23+P23 | R23: =Q23*Campaign_Days-B23
A24: 1. r3 c6 | B24: =Sensitivity!$B$9 | C24: =Locals_Share_Ceiling | D24: =Sensitivity!H$6 | E24: =Average_PWYW | F24: =Local_AudioTour_Rate_PWYW | G24: =Percentage_Locals_Init+(C24-Percentage_Locals_Init)*(1-EXP(-B24/Marketing_Saturation_Spend)) | H24: =Tourists_Base*G24/(1-G24) | I24: =H24-Locals_Base | J24: =Locals_Base*(1-(1-EXP(-B24/Marketing_Saturation_Spend)))*Local_AudioTour_Rate_Init+(H24-Locals_Base*(1-(1-EXP(-B24/Marketing_Saturation_Spend))))*F24 | K24: =AudioTourist_Base+J24 | L24: =MAX(0,ROUNDUP((K24-Device_Capacity)/Device_Block_Size,0)) | M24: =L24*Device_Block_Cost/Device_Amort_Days | N24: =Fee_Keep*(Locals_Base*(1-(1-EXP(-B24/Marketing_Saturation_Spend)))*Local_AudioTour_Rate_Init*AudioTour_Price+(H24-Locals_Base*(1-(1-EXP(-B24/Marketing_Saturation_Spend))))*F24*E24-AudioLocal_Base*AudioTour_Price) | O24: =(K24-Total_Daily_AudioTour)*Headset_Cost | P24: =I24*D24+Locals_Base*(1-EXP(-B24/Marketing_Saturation_Spend))*F24*GiftShop_Spillover | Q24: =N24-O24-M24+P24 | R24: =Q24*Campaign_Days-B24
A25: 1. r3 c7 | B25: =Sensitivity!$B$9 | C25: =Locals_Share_Ceiling | D25: =Sensitivity!I$6 | E25: =Average_PWYW | F25: =Local_AudioTour_Rate_PWYW | G25: =Percentage_Locals_Init+(C25-Percentage_Locals_Init)*(1-EXP(-B25/Marketing_Saturation_Spend)) | H25: =Tourists_Base*G25/(1-G25) | I25: =H25-Locals_Base | J25: =Locals_Base*(1-(1-EXP(-B25/Marketing_Saturation_Spend)))*Local_AudioTour_Rate_Init+(H25-Locals_Base*(1-(1-EXP(-B25/Marketing_Saturation_Spend))))*F25 | K25: =AudioTourist_Base+J25 | L25: =MAX(0,ROUNDUP((K25-Device_Capacity)/Device_Block_Size,0)) | M25: =L25*Device_Block_Cost/Device_Amort_Days | N25: =Fee_Keep*(Locals_Base*(1-(1-EXP(-B25/Marketing_Saturation_Spend)))*Local_AudioTour_Rate_Init*AudioTour_Price+(H25-Locals_Base*(1-(1-EXP(-B25/Marketing_Saturation_Spend))))*F25*E25-AudioLocal_Base*AudioTour_Price) | O25: =(K25-Total_Daily_AudioTour)*Headset_Cost | P25: =I25*D25+Locals_Base*(1-EXP(-B25/Marketing_Saturation_Spend))*F25*GiftShop_Spillover | Q25: =N25-O25-M25+P25 | R25: =Q25*Campaign_Days-B25
A26: 1. r4 c1 | B26: =Sensitivity!$B$10 | C26: =Locals_Share_Ceiling | D26: =Sensitivity!C$6 | E26: =Average_PWYW | F26: =Local_AudioTour_Rate_PWYW | G26: =Percentage_Locals_Init+(C26-Percentage_Locals_Init)*(1-EXP(-B26/Marketing_Saturation_Spend)) | H26: =Tourists_Base*G26/(1-G26) | I26: =H26-Locals_Base | J26: =Locals_Base*(1-(1-EXP(-B26/Marketing_Saturation_Spend)))*Local_AudioTour_Rate_Init+(H26-Locals_Base*(1-(1-EXP(-B26/Marketing_Saturation_Spend))))*F26 | K26: =AudioTourist_Base+J26 | L26: =MAX(0,ROUNDUP((K26-Device_Capacity)/Device_Block_Size,0)) | M26: =L26*Device_Block_Cost/Device_Amort_Days | N26: =Fee_Keep*(Locals_Base*(1-(1-EXP(-B26/Marketing_Saturation_Spend)))*Local_AudioTour_Rate_Init*AudioTour_Price+(H26-Locals_Base*(1-(1-EXP(-B26/Marketing_Saturation_Spend))))*F26*E26-AudioLocal_Base*AudioTour_Price) | O26: =(K26-Total_Daily_AudioTour)*Headset_Cost | P26: =I26*D26+Locals_Base*(1-EXP(-B26/Marketing_Saturation_Spend))*F26*GiftShop_Spillover | Q26: =N26-O26-M26+P26 | R26: =Q26*Campaign_Days-B26
A27: 1. r4 c2 | B27: =Sensitivity!$B$10 | C27: =Locals_Share_Ceiling | D27: =Sensitivity!D$6 | E27: =Average_PWYW | F27: =Local_AudioTour_Rate_PWYW | G27: =Percentage_Locals_Init+(C27-Percentage_Locals_Init)*(1-EXP(-B27/Marketing_Saturation_Spend)) | H27: =Tourists_Base*G27/(1-G27) | I27: =H27-Locals_Base | J27: =Locals_Base*(1-(1-EXP(-B27/Marketing_Saturation_Spend)))*Local_AudioTour_Rate_Init+(H27-Locals_Base*(1-(1-EXP(-B27/Marketing_Saturation_Spend))))*F27 | K27: =AudioTourist_Base+J27 | L27: =MAX(0,ROUNDUP((K27-Device_Capacity)/Device_Block_Size,0)) | M27: =L27*Device_Block_Cost/Device_Amort_Days | N27: =Fee_Keep*(Locals_Base*(1-(1-EXP(-B27/Marketing_Saturation_Spend)))*Local_AudioTour_Rate_Init*AudioTour_Price+(H27-Locals_Base*(1-(1-EXP(-B27/Marketing_Saturation_Spend))))*F27*E27-AudioLocal_Base*AudioTour_Price) | O27: =(K27-Total_Daily_AudioTour)*Headset_Cost | P27: =I27*D27+Locals_Base*(1-EXP(-B27/Marketing_Saturation_Spend))*F27*GiftShop_Spillover | Q27: =N27-O27-M27+P27 | R27: =Q27*Campaign_Days-B27
A28: 1. r4 c3 | B28: =Sensitivity!$B$10 | C28: =Locals_Share_Ceiling | D28: =Sensitivity!E$6 | E28: =Average_PWYW | F28: =Local_AudioTour_Rate_PWYW | G28: =Percentage_Locals_Init+(C28-Percentage_Locals_Init)*(1-EXP(-B28/Marketing_Saturation_Spend)) | H28: =Tourists_Base*G28/(1-G28) | I28: =H28-Locals_Base | J28: =Locals_Base*(1-(1-EXP(-B28/Marketing_Saturation_Spend)))*Local_AudioTour_Rate_Init+(H28-Locals_Base*(1-(1-EXP(-B28/Marketing_Saturation_Spend))))*F28 | K28: =AudioTourist_Base+J28 | L28: =MAX(0,ROUNDUP((K28-Device_Capacity)/Device_Block_Size,0)) | M28: =L28*Device_Block_Cost/Device_Amort_Days | N28: =Fee_Keep*(Locals_Base*(1-(1-EXP(-B28/Marketing_Saturation_Spend)))*Local_AudioTour_Rate_Init*AudioTour_Price+(H28-Locals_Base*(1-(1-EXP(-B28/Marketing_Saturation_Spend))))*F28*E28-AudioLocal_Base*AudioTour_Price) | O28: =(K28-Total_Daily_AudioTour)*Headset_Cost | P28: =I28*D28+Locals_Base*(1-EXP(-B28/Marketing_Saturation_Spend))*F28*GiftShop_Spillover | Q28: =N28-O28-M28+P28 | R28: =Q28*Campaign_Days-B28
A29: 1. r4 c4 | B29: =Sensitivity!$B$10 | C29: =Locals_Share_Ceiling | D29: =Sensitivity!F$6 | E29: =Average_PWYW | F29: =Local_AudioTour_Rate_PWYW | G29: =Percentage_Locals_Init+(C29-Percentage_Locals_Init)*(1-EXP(-B29/Marketing_Saturation_Spend)) | H29: =Tourists_Base*G29/(1-G29) | I29: =H29-Locals_Base | J29: =Locals_Base*(1-(1-EXP(-B29/Marketing_Saturation_Spend)))*Local_AudioTour_Rate_Init+(H29-Locals_Base*(1-(1-EXP(-B29/Marketing_Saturation_Spend))))*F29 | K29: =AudioTourist_Base+J29 | L29: =MAX(0,ROUNDUP((K29-Device_Capacity)/Device_Block_Size,0)) | M29: =L29*Device_Block_Cost/Device_Amort_Days | N29: =Fee_Keep*(Locals_Base*(1-(1-EXP(-B29/Marketing_Saturation_Spend)))*Local_AudioTour_Rate_Init*AudioTour_Price+(H29-Locals_Base*(1-(1-EXP(-B29/Marketing_Saturation_Spend))))*F29*E29-AudioLocal_Base*AudioTour_Price) | O29: =(K29-Total_Daily_AudioTour)*Headset_Cost | P29: =I29*D29+Locals_Base*(1-EXP(-B29/Marketing_Saturation_Spend))*F29*GiftShop_Spillover | Q29: =N29-O29-M29+P29 | R29: =Q29*Campaign_Days-B29
A30: 1. r4 c5 | B30: =Sensitivity!$B$10 | C30: =Locals_Share_Ceiling | D30: =Sensitivity!G$6 | E30: =Average_PWYW | F30: =Local_AudioTour_Rate_PWYW | G30: =Percentage_Locals_Init+(C30-Percentage_Locals_Init)*(1-EXP(-B30/Marketing_Saturation_Spend)) | H30: =Tourists_Base*G30/(1-G30) | I30: =H30-Locals_Base | J30: =Locals_Base*(1-(1-EXP(-B30/Marketing_Saturation_Spend)))*Local_AudioTour_Rate_Init+(H30-Locals_Base*(1-(1-EXP(-B30/Marketing_Saturation_Spend))))*F30 | K30: =AudioTourist_Base+J30 | L30: =MAX(0,ROUNDUP((K30-Device_Capacity)/Device_Block_Size,0)) | M30: =L30*Device_Block_Cost/Device_Amort_Days | N30: =Fee_Keep*(Locals_Base*(1-(1-EXP(-B30/Marketing_Saturation_Spend)))*Local_AudioTour_Rate_Init*AudioTour_Price+(H30-Locals_Base*(1-(1-EXP(-B30/Marketing_Saturation_Spend))))*F30*E30-AudioLocal_Base*AudioTour_Price) | O30: =(K30-Total_Daily_AudioTour)*Headset_Cost | P30: =I30*D30+Locals_Base*(1-EXP(-B30/Marketing_Saturation_Spend))*F30*GiftShop_Spillover | Q30: =N30-O30-M30+P30 | R30: =Q30*Campaign_Days-B30
A31: 1. r4 c6 | B31: =Sensitivity!$B$10 | C31: =Locals_Share_Ceiling | D31: =Sensitivity!H$6 | E31: =Average_PWYW | F31: =Local_AudioTour_Rate_PWYW | G31: =Percentage_Locals_Init+(C31-Percentage_Locals_Init)*(1-EXP(-B31/Marketing_Saturation_Spend)) | H31: =Tourists_Base*G31/(1-G31) | I31: =H31-Locals_Base | J31: =Locals_Base*(1-(1-EXP(-B31/Marketing_Saturation_Spend)))*Local_AudioTour_Rate_Init+(H31-Locals_Base*(1-(1-EXP(-B31/Marketing_Saturation_Spend))))*F31 | K31: =AudioTourist_Base+J31 | L31: =MAX(0,ROUNDUP((K31-Device_Capacity)/Device_Block_Size,0)) | M31: =L31*Device_Block_Cost/Device_Amort_Days | N31: =Fee_Keep*(Locals_Base*(1-(1-EXP(-B31/Marketing_Saturation_Spend)))*Local_AudioTour_Rate_Init*AudioTour_Price+(H31-Locals_Base*(1-(1-EXP(-B31/Marketing_Saturation_Spend))))*F31*E31-AudioLocal_Base*AudioTour_Price) | O31: =(K31-Total_Daily_AudioTour)*Headset_Cost | P31: =I31*D31+Locals_Base*(1-EXP(-B31/Marketing_Saturation_Spend))*F31*GiftShop_Spillover | Q31: =N31-O31-M31+P31 | R31: =Q31*Campaign_Days-B31
A32: 1. r4 c7 | B32: =Sensitivity!$B$10 | C32: =Locals_Share_Ceiling | D32: =Sensitivity!I$6 | E32: =Average_PWYW | F32: =Local_AudioTour_Rate_PWYW | G32: =Percentage_Locals_Init+(C32-Percentage_Locals_Init)*(1-EXP(-B32/Marketing_Saturation_Spend)) | H32: =Tourists_Base*G32/(1-G32) | I32: =H32-Locals_Base | J32: =Locals_Base*(1-(1-EXP(-B32/Marketing_Saturation_Spend)))*Local_AudioTour_Rate_Init+(H32-Locals_Base*(1-(1-EXP(-B32/Marketing_Saturation_Spend))))*F32 | K32: =AudioTourist_Base+J32 | L32: =MAX(0,ROUNDUP((K32-Device_Capacity)/Device_Block_Size,0)) | M32: =L32*Device_Block_Cost/Device_Amort_Days | N32: =Fee_Keep*(Locals_Base*(1-(1-EXP(-B32/Marketing_Saturation_Spend)))*Local_AudioTour_Rate_Init*AudioTour_Price+(H32-Locals_Base*(1-(1-EXP(-B32/Marketing_Saturation_Spend))))*F32*E32-AudioLocal_Base*AudioTour_Price) | O32: =(K32-Total_Daily_AudioTour)*Headset_Cost | P32: =I32*D32+Locals_Base*(1-EXP(-B32/Marketing_Saturation_Spend))*F32*GiftShop_Spillover | Q32: =N32-O32-M32+P32 | R32: =Q32*Campaign_Days-B32
A33: 1. r5 c1 | B33: =Sensitivity!$B$11 | C33: =Locals_Share_Ceiling | D33: =Sensitivity!C$6 | E33: =Average_PWYW | F33: =Local_AudioTour_Rate_PWYW | G33: =Percentage_Locals_Init+(C33-Percentage_Locals_Init)*(1-EXP(-B33/Marketing_Saturation_Spend)) | H33: =Tourists_Base*G33/(1-G33) | I33: =H33-Locals_Base | J33: =Locals_Base*(1-(1-EXP(-B33/Marketing_Saturation_Spend)))*Local_AudioTour_Rate_Init+(H33-Locals_Base*(1-(1-EXP(-B33/Marketing_Saturation_Spend))))*F33 | K33: =AudioTourist_Base+J33 | L33: =MAX(0,ROUNDUP((K33-Device_Capacity)/Device_Block_Size,0)) | M33: =L33*Device_Block_Cost/Device_Amort_Days | N33: =Fee_Keep*(Locals_Base*(1-(1-EXP(-B33/Marketing_Saturation_Spend)))*Local_AudioTour_Rate_Init*AudioTour_Price+(H33-Locals_Base*(1-(1-EXP(-B33/Marketing_Saturation_Spend))))*F33*E33-AudioLocal_Base*AudioTour_Price) | O33: =(K33-Total_Daily_AudioTour)*Headset_Cost | P33: =I33*D33+Locals_Base*(1-EXP(-B33/Marketing_Saturation_Spend))*F33*GiftShop_Spillover | Q33: =N33-O33-M33+P33 | R33: =Q33*Campaign_Days-B33
A34: 1. r5 c2 | B34: =Sensitivity!$B$11 | C34: =Locals_Share_Ceiling | D34: =Sensitivity!D$6 | E34: =Average_PWYW | F34: =Local_AudioTour_Rate_PWYW | G34: =Percentage_Locals_Init+(C34-Percentage_Locals_Init)*(1-EXP(-B34/Marketing_Saturation_Spend)) | H34: =Tourists_Base*G34/(1-G34) | I34: =H34-Locals_Base | J34: =Locals_Base*(1-(1-EXP(-B34/Marketing_Saturation_Spend)))*Local_AudioTour_Rate_Init+(H34-Locals_Base*(1-(1-EXP(-B34/Marketing_Saturation_Spend))))*F34 | K34: =AudioTourist_Base+J34 | L34: =MAX(0,ROUNDUP((K34-Device_Capacity)/Device_Block_Size,0)) | M34: =L34*Device_Block_Cost/Device_Amort_Days | N34: =Fee_Keep*(Locals_Base*(1-(1-EXP(-B34/Marketing_Saturation_Spend)))*Local_AudioTour_Rate_Init*AudioTour_Price+(H34-Locals_Base*(1-(1-EXP(-B34/Marketing_Saturation_Spend))))*F34*E34-AudioLocal_Base*AudioTour_Price) | O34: =(K34-Total_Daily_AudioTour)*Headset_Cost | P34: =I34*D34+Locals_Base*(1-EXP(-B34/Marketing_Saturation_Spend))*F34*GiftShop_Spillover | Q34: =N34-O34-M34+P34 | R34: =Q34*Campaign_Days-B34
A35: 1. r5 c3 | B35: =Sensitivity!$B$11 | C35: =Locals_Share_Ceiling | D35: =Sensitivity!E$6 | E35: =Average_PWYW | F35: =Local_AudioTour_Rate_PWYW | G35: =Percentage_Locals_Init+(C35-Percentage_Locals_Init)*(1-EXP(-B35/Marketing_Saturation_Spend)) | H35: =Tourists_Base*G35/(1-G35) | I35: =H35-Locals_Base | J35: =Locals_Base*(1-(1-EXP(-B35/Marketing_Saturation_Spend)))*Local_AudioTour_Rate_Init+(H35-Locals_Base*(1-(1-EXP(-B35/Marketing_Saturation_Spend))))*F35 | K35: =AudioTourist_Base+J35 | L35: =MAX(0,ROUNDUP((K35-Device_Capacity)/Device_Block_Size,0)) | M35: =L35*Device_Block_Cost/Device_Amort_Days | N35: =Fee_Keep*(Locals_Base*(1-(1-EXP(-B35/Marketing_Saturation_Spend)))*Local_AudioTour_Rate_Init*AudioTour_Price+(H35-Locals_Base*(1-(1-EXP(-B35/Marketing_Saturation_Spend))))*F35*E35-AudioLocal_Base*AudioTour_Price) | O35: =(K35-Total_Daily_AudioTour)*Headset_Cost | P35: =I35*D35+Locals_Base*(1-EXP(-B35/Marketing_Saturation_Spend))*F35*GiftShop_Spillover | Q35: =N35-O35-M35+P35 | R35: =Q35*Campaign_Days-B35
A36: 1. r5 c4 | B36: =Sensitivity!$B$11 | C36: =Locals_Share_Ceiling | D36: =Sensitivity!F$6 | E36: =Average_PWYW | F36: =Local_AudioTour_Rate_PWYW | G36: =Percentage_Locals_Init+(C36-Percentage_Locals_Init)*(1-EXP(-B36/Marketing_Saturation_Spend)) | H36: =Tourists_Base*G36/(1-G36) | I36: =H36-Locals_Base | J36: =Locals_Base*(1-(1-EXP(-B36/Marketing_Saturation_Spend)))*Local_AudioTour_Rate_Init+(H36-Locals_Base*(1-(1-EXP(-B36/Marketing_Saturation_Spend))))*F36 | K36: =AudioTourist_Base+J36 | L36: =MAX(0,ROUNDUP((K36-Device_Capacity)/Device_Block_Size,0)) | M36: =L36*Device_Block_Cost/Device_Amort_Days | N36: =Fee_Keep*(Locals_Base*(1-(1-EXP(-B36/Marketing_Saturation_Spend)))*Local_AudioTour_Rate_Init*AudioTour_Price+(H36-Locals_Base*(1-(1-EXP(-B36/Marketing_Saturation_Spend))))*F36*E36-AudioLocal_Base*AudioTour_Price) | O36: =(K36-Total_Daily_AudioTour)*Headset_Cost | P36: =I36*D36+Locals_Base*(1-EXP(-B36/Marketing_Saturation_Spend))*F36*GiftShop_Spillover | Q36: =N36-O36-M36+P36 | R36: =Q36*Campaign_Days-B36
A37: 1. r5 c5 | B37: =Sensitivity!$B$11 | C37: =Locals_Share_Ceiling | D37: =Sensitivity!G$6 | E37: =Average_PWYW | F37: =Local_AudioTour_Rate_PWYW | G37: =Percentage_Locals_Init+(C37-Percentage_Locals_Init)*(1-EXP(-B37/Marketing_Saturation_Spend)) | H37: =Tourists_Base*G37/(1-G37) | I37: =H37-Locals_Base | J37: =Locals_Base*(1-(1-EXP(-B37/Marketing_Saturation_Spend)))*Local_AudioTour_Rate_Init+(H37-Locals_Base*(1-(1-EXP(-B37/Marketing_Saturation_Spend))))*F37 | K37: =AudioTourist_Base+J37 | L37: =MAX(0,ROUNDUP((K37-Device_Capacity)/Device_Block_Size,0)) | M37: =L37*Device_Block_Cost/Device_Amort_Days | N37: =Fee_Keep*(Locals_Base*(1-(1-EXP(-B37/Marketing_Saturation_Spend)))*Local_AudioTour_Rate_Init*AudioTour_Price+(H37-Locals_Base*(1-(1-EXP(-B37/Marketing_Saturation_Spend))))*F37*E37-AudioLocal_Base*AudioTour_Price) | O37: =(K37-Total_Daily_AudioTour)*Headset_Cost | P37: =I37*D37+Locals_Base*(1-EXP(-B37/Marketing_Saturation_Spend))*F37*GiftShop_Spillover | Q37: =N37-O37-M37+P37 | R37: =Q37*Campaign_Days-B37
A38: 1. r5 c6 | B38: =Sensitivity!$B$11 | C38: =Locals_Share_Ceiling | D38: =Sensitivity!H$6 | E38: =Average_PWYW | F38: =Local_AudioTour_Rate_PWYW | G38: =Percentage_Locals_Init+(C38-Percentage_Locals_Init)*(1-EXP(-B38/Marketing_Saturation_Spend)) | H38: =Tourists_Base*G38/(1-G38) | I38: =H38-Locals_Base | J38: =Locals_Base*(1-(1-EXP(-B38/Marketing_Saturation_Spend)))*Local_AudioTour_Rate_Init+(H38-Locals_Base*(1-(1-EXP(-B38/Marketing_Saturation_Spend))))*F38 | K38: =AudioTourist_Base+J38 | L38: =MAX(0,ROUNDUP((K38-Device_Capacity)/Device_Block_Size,0)) | M38: =L38*Device_Block_Cost/Device_Amort_Days | N38: =Fee_Keep*(Locals_Base*(1-(1-EXP(-B38/Marketing_Saturation_Spend)))*Local_AudioTour_Rate_Init*AudioTour_Price+(H38-Locals_Base*(1-(1-EXP(-B38/Marketing_Saturation_Spend))))*F38*E38-AudioLocal_Base*AudioTour_Price) | O38: =(K38-Total_Daily_AudioTour)*Headset_Cost | P38: =I38*D38+Locals_Base*(1-EXP(-B38/Marketing_Saturation_Spend))*F38*GiftShop_Spillover | Q38: =N38-O38-M38+P38 | R38: =Q38*Campaign_Days-B38
A39: 1. r5 c7 | B39: =Sensitivity!$B$11 | C39: =Locals_Share_Ceiling | D39: =Sensitivity!I$6 | E39: =Average_PWYW | F39: =Local_AudioTour_Rate_PWYW | G39: =Percentage_Locals_Init+(C39-Percentage_Locals_Init)*(1-EXP(-B39/Marketing_Saturation_Spend)) | H39: =Tourists_Base*G39/(1-G39) | I39: =H39-Locals_Base | J39: =Locals_Base*(1-(1-EXP(-B39/Marketing_Saturation_Spend)))*Local_AudioTour_Rate_Init+(H39-Locals_Base*(1-(1-EXP(-B39/Marketing_Saturation_Spend))))*F39 | K39: =AudioTourist_Base+J39 | L39: =MAX(0,ROUNDUP((K39-Device_Capacity)/Device_Block_Size,0)) | M39: =L39*Device_Block_Cost/Device_Amort_Days | N39: =Fee_Keep*(Locals_Base*(1-(1-EXP(-B39/Marketing_Saturation_Spend)))*Local_AudioTour_Rate_Init*AudioTour_Price+(H39-Locals_Base*(1-(1-EXP(-B39/Marketing_Saturation_Spend))))*F39*E39-AudioLocal_Base*AudioTour_Price) | O39: =(K39-Total_Daily_AudioTour)*Headset_Cost | P39: =I39*D39+Locals_Base*(1-EXP(-B39/Marketing_Saturation_Spend))*F39*GiftShop_Spillover | Q39: =N39-O39-M39+P39 | R39: =Q39*Campaign_Days-B39
A40: 1. r6 c1 | B40: =Sensitivity!$B$12 | C40: =Locals_Share_Ceiling | D40: =Sensitivity!C$6 | E40: =Average_PWYW | F40: =Local_AudioTour_Rate_PWYW | G40: =Percentage_Locals_Init+(C40-Percentage_Locals_Init)*(1-EXP(-B40/Marketing_Saturation_Spend)) | H40: =Tourists_Base*G40/(1-G40) | I40: =H40-Locals_Base | J40: =Locals_Base*(1-(1-EXP(-B40/Marketing_Saturation_Spend)))*Local_AudioTour_Rate_Init+(H40-Locals_Base*(1-(1-EXP(-B40/Marketing_Saturation_Spend))))*F40 | K40: =AudioTourist_Base+J40 | L40: =MAX(0,ROUNDUP((K40-Device_Capacity)/Device_Block_Size,0)) | M40: =L40*Device_Block_Cost/Device_Amort_Days | N40: =Fee_Keep*(Locals_Base*(1-(1-EXP(-B40/Marketing_Saturation_Spend)))*Local_AudioTour_Rate_Init*AudioTour_Price+(H40-Locals_Base*(1-(1-EXP(-B40/Marketing_Saturation_Spend))))*F40*E40-AudioLocal_Base*AudioTour_Price) | O40: =(K40-Total_Daily_AudioTour)*Headset_Cost | P40: =I40*D40+Locals_Base*(1-EXP(-B40/Marketing_Saturation_Spend))*F40*GiftShop_Spillover | Q40: =N40-O40-M40+P40 | R40: =Q40*Campaign_Days-B40
...

Sheet Lists
A1: Marketing ($)
A2: 0
A3: 2500
A4: 5000
A5: 7500
A6: 10000
A7: 12500
A8: 15000
A9: 17500
A10: 20000
